Workbook

Sheet README
A1: State Vehicles 2024 — SSYVbT Baseline Workbook
A3: Built: 2026-08-11 14:53
A4: Scope: 48 contiguous U.S. states + DC, vehicle stock counts, 2024 baseline
A5: Output: 12 SSYVbT-* tabs (one per segment x mode), state rows x 7 fuel-tech columns
A6: Methodology: docs/methodology/state-vehicles-2024.md
A7: Generator: outputs/SYVbT/_build_syvbt_v1_helpers.py
A9: Data tabs (sources)
A11: Tab | B11: Rows | C11: Source
A12: Keys | B12: 62 | C12: Authored — single source of truth for string/numeric constants (CLAUDE.md style).
A13: FHWA_MV1 | B13: 62 | C13: sources/raw/fhwa/mv1.xlsx (verbatim, FHWA Highway Statistics 2024)
A14: AFDC_EV_state | B14: 52 | C14: AFDC 2023 EV-only state counts (legacy; cross-check vs 2024 multi-fuel table).
A15: AFDC_state_fuel_2024 | B15: 55 | C15: AFDC 2024 Light-Duty Vehicle Registration Counts by State and Fuel Type. Source: afdc.energy.gov/vehicle-registration (12 fuel types × 50 states + DC + US). Derived by National Laboratory of the Rockies from Experian data.
A16: State_shares_nonroad | B16: 53 | C16: sources/Subregion ... | sheet % by state 2019
A17: US_syvbt_psgr_totals | B17: 6 | C17: sources/Subregion ... | sheet US-syvbt-psgr
A18: US_syvbt_frgt_totals | B18: 6 | C18: sources/Subregion ... | sheet US-syvbt-frgt
A19: State_lookup | B19: 48 | C19: Per-state input lookups (FHWA + AFDC + non-road shares); FHWA envelope re-anchored to AFDC for Keys!stock_fix_states (NY/MT/DE, sec 9.6).
A20: National_totals | B20: 12 | C20: AEO 2026 national fleet stock by (segment, mode, fuel-tech).
A21: AFDC_state_fuels_lookup | B21: 48 | C21: Per-state per-EPS-fuel-tech direct counts from AFDC 2024 (BEV / PHEV / NGV / gas / dsl / LPG / H2).
A22: SSYVbT-* (12 tabs) | B22: 48 | C22: v2 OUTPUT: state direct counts × national fuel-tech share (road modes); national × state share (non-road).
A23: SYVbT-passenger/freight | B23: 6 | C23: Per-state EPS input matrices (6 modes x 7 techs), driven by About!B1 selector.

Sheet About
A1: Workbook | B1: Maine | C1: 46245 | E1: State | F1: State
A2: State Vehicle Counts 2024 v2 — DIRECT state data (exploratory variant) | B2: =INDEX(F:F,MATCH(B1,E:E,0)) -> ME | E2: Alabama | F2: AL
E3: Arizona | F3: AZ
A4: Output: | B4: 12 SSYVbT-* tabs, IA reference format (states × 7 fuel-techs). | E4: Arkansas | F4: AR
A5: Methodology: | B5: docs/methodology/state-vehicles-2024.md (v2 section) | E5: California | F5: CA
A6: Generator: | B6: outputs/SYVbT/_build_syvbt_workbook.py | E6: Colorado | F6: CO
A7: Baseline year: | B7: =Keys!$C$2 -> 2024 | E7: Connecticut | F7: CT
E8: Delaware | F8: DE
A9: How v2 differs from v1 | E9: Florida | F9: FL
A10: v1 anchors to AEO 2026 national totals; per-cell formula = nat_total × state_share. | E10: Georgia | F10: GA
A11: v2 anchors to direct STATE data (FHWA MV-1 + AFDC EV); per-cell formula = state_total × nat_fuel_tech_share. | E11: Idaho | F11: ID
E12: Illinois | F12: IL
A13: For modes WITH direct state data (LDVs, HDVs, motorbikes), v2 trusts FHWA/AFDC over AEO. | E13: Indiana | F13: IN
A14: State sums for these modes will NOT match AEO national — by design. | E14: Iowa | F14: IA
E15: Kansas | F15: KS
A16: For modes WITHOUT direct state data (aircraft, rail, ships), v2 falls back to v1 logic | E16: Kentucky | F16: KY
A17: (state_share × national_total) — there is no direct alternative. | E17: Louisiana | F17: LA
E18: Maine | F18: ME
A19: Production (v1) feeds EPS. v2 is exploratory — useful for sanity-checking AEO | E19: Maryland | F19: MD
A20: national totals against bottom-up FHWA + AFDC observations. | E20: Massachusetts | F20: MA
E21: Michigan | F21: MI
A22: Per organizational guidance: outputs framed as inputs for staff review. Verify against | E22: Minnesota | F22: MN
A23: primary sources (FHWA, AFDC, AEO) before incorporating in published work. | E23: Mississippi | F23: MS
E24: Missouri | F24: MO
E25: Montana | F25: MT
E26: Nebraska | F26: NE
E27: Nevada | F27: NV
E28: New Hampshire | F28: NH
E29: New Jersey | F29: NJ
E30: New Mexico | F30: NM
E31: New York | F31: NY
E32: North Carolina | F32: NC
E33: North Dakota | F33: ND
E34: Ohio | F34: OH
E35: Oklahoma | F35: OK
... E49: Wyoming | F49: WY

Sheet Methodology
A1: State Vehicles 2024 v2 — Direct-State-Data Variant
A2: Built: 2026-08-11
A4: Goal
A5: Same scope as v1 (50 × 12 × 7 cube of vehicle counts for 2024) but with a DIFFERENT methodology that prioritizes direct state observations over AEO national totals. v2 is an exploratory variant; v1 remains the production / EPS-feeding workbook per CLAUDE.md convention.
A7: v1 vs v2 formula contrast
A8: v1 per-cell formula: state_count = national_total[seg, mode, ft] × state_share[s, seg, mode] where state_share normalizes to 1 across contiguous states. Consequence: state-sum reconciles to national exactly (within rounding). v2 per-cell formula (when direct state data exists): state_count = state_total[s, seg, mode] × national_fuel_tech_share[seg, mode, ft] where state_total comes from FHWA MV-1 / AFDC directly. Consequence: state-sum does NOT reconcile to national — discrepancy is information.
A10: Mode-by-mode v2 logic
A11: passenger LDV BEV/PHEV — DIRECT: AFDC_EV[state] × BEV-or-PHEV split (no scaling). passenger LDV gas/dsl/NGV/LPG/H2 — DIRECT: FHWA Autos[state] × national fuel-tech share (share = nat_ft / nat_LDV_psgr_total). passenger HDV (buses) — DIRECT: FHWA Buses[state] × national bus fuel-tech share. freight LDV — DIRECT: FHWA Trucks[state] × light_share × frgt_share × national fuel-tech share. freight HDV — DIRECT: FHWA Trucks[state] × heavy_share × national fuel-tech share. passenger motorbikes — DIRECT: FHWA Motorcycles[state] × national fuel-tech share (basically 100% gas). freight motorbikes — DIRECT: 0 (per EPS convention; no freight motorbikes). passenger aircraft — SCALED: state_share (FAA enplanements) × national passenger aircraft. freight aircraft — SCALED: state_share (FAA cargo landed weight) × national freight aircraft. passenger rail — SCALED: state_share (APTA diesel-or-electric) × national passenger rail. freight rail — SCALED: state_share (AAR carloads) × national freight rail. passenger ships — SCALED: state_share (BTS recreational boats) × national passenger ships. freight ships — SCALED: state_share (BTS port tonnage) × national freight ships.
A13: Interpretation of v2 STATE SUM vs NATIONAL (AEO) deltas
A14: Each SSYVbT-* tab carries STATE SUM / NATIONAL (AEO) / DELTA % rows at the bottom. In v1 these deltas are forced to ~0% by construction. In v2 they reveal real disagreement between bottom-up FHWA/AFDC and top-down AEO 2026: Large positive delta = FHWA/AFDC observe MORE vehicles than AEO projects (likely AEO under-estimates total stock; common for trucks and aging fleets). Large negative delta = FHWA/AFDC observe FEWER vehicles than AEO projects (likely AEO over-estimates fleet turnover; e.g., for early-adoption tech like EVs). Staff should treat large deltas as a flag for which data source to trust per use case. For EPS calibration purposes (per locked v1 convention), use v1 numbers. For ground-truth state vehicle stock comparisons, v2 may be more useful.
A16: When v1 matches v2 and when they differ
A17: Identical: aircraft, rail, ships (passenger + freight) — no direct state data so both variants use national × state_share. Differ: LDVs, HDVs, motorbikes (passenger + freight) — v2 uses FHWA/AFDC counts directly.
... A23: python outputs/SYVbT/_build_syvbt_workbook.py

Sheet Keys
A1: category | B1: key | C1: value | D1: description
A2: meta | B2: baseline_year | C2: 2024 | D2: Vehicle count target year. FHWA Highway Statistics 2024 was released January 2026 (actual state-reported data).
A3: meta | B3: afdc_vintage | C3: 2023 | D3: AFDC EV state-count vintage. Latest bulk-download file from afdc.energy.gov was Sep 2024 (2023 data). Per user decision #1, fall back to 2023 when 2024 unavailable.
A4: meta | B4: aeo_vintage | C4: 2026 | D4: AEO 2026 reference scenario; national fleet stock totals.
A5: segment | B5: passenger | C5: passenger | D5: EPS passenger segment label.
A6: segment | B6: freight | C6: freight | D6: EPS freight segment label.
A7: mode | B7: LDVs | C7: LDVs | D7: Light-duty vehicles (cars + light pickups).
A8: mode | B8: HDVs | C8: HDVs | D8: Heavy-duty vehicles (buses [passenger] + heavy commercial trucks [freight]).
A9: mode | B9: aircraft | C9: aircraft | D9: Aircraft.
A10: mode | B10: rail | C10: rail | D10: Rail (passenger + freight).
A11: mode | B11: ships | C11: ships | D11: Marine vessels.
A12: mode | B12: motorbikes | C12: motorbikes | D12: Motorcycles + motorbikes.
A13: fuel_tech | B13: BEV | C13: battery electric vehicle | D13: EPS battery electric vehicle.
A14: fuel_tech | B14: NGV | C14: natural gas vehicle | D14: EPS natural gas vehicle.
A15: fuel_tech | B15: gas | C15: gasoline vehicle | D15: EPS gasoline vehicle. Includes E85 / methanol per AFDC->EPS crosswalk.
A16: fuel_tech | B16: dsl | C16: diesel vehicle | D16: EPS diesel vehicle. Includes biodiesel; jet fuel for aircraft; bunker for ships.
... A26: afdc | B26: col_ev_count | C26: C | D26: AFDC_EV_state column C: BEV+PHEV combined registration count (2023 reference).
A27: national_split | B27: bev_share_of_evs | C27: 0.76 | D27: National BEV / (BEV+PHEV) share. AEO 2026 T39 implied; cross-checked against AFDC change tab.
A28: national_split | B28: phev_share_of_evs | C28: 0.24 | D28: National PHEV / (BEV+PHEV) share. Complement of bev_share_of_evs.
A29: national_split | B29: freight_share_of_LDVs | C29: 0.045 | D29: Freight LDV (commercial light truck) share of total light vehicles. AEO 2026 T45 / (T39 LDV + T45) ~ 4.5%. Applied uniformly across states (state-level commercial-vs-personal split unobserved without FHWA MV-9; pending v2.1 if MV-9 is republished).
A30: national_split | B30: passenger_share_of_LDVs | C30: 0.955 | D30: Passenger LDV (personal cars + personal pickups) share of total light vehicles. Complement of freight_share_of_LDVs.
A31: national_split | B31: heavy_share_of_FHWA_trucks | C31: 0.037 | D31: Heavy commercial truck share of FHWA MV-1 "Trucks" column. AEO T49 freight truck stock / total truck stock. Used to split FHWA trucks into freight HDV (heavy) vs LDV (light).
A32: national_split | B32: light_share_of_FHWA_trucks | C32: 0.963 | D32: Light truck share of FHWA MV-1 "Trucks" column. Complement of heavy_share_of_FHWA_trucks.
A33: nonroad_shares | B33: col_state_air | C33: J | D33: State_shares_nonroad col J: state ABBR for aircraft shares.
A34: nonroad_shares | B34: col_psgr_air | C34: K | D34: State_shares_nonroad col K: passenger aircraft state share (FAA enplanements 2019).
A35: nonroad_shares | B35: col_frgt_air | C35: L | D35: State_shares_nonroad col L: freight aircraft state share (FAA cargo landed weight 2019).
A36: nonroad_shares | B36: col_state_psgr_rail | C36: O | D36: State_shares_nonroad col O: state ABBR for passenger rail.
A37: nonroad_shares | B37: col_psgr_rail_diesel | C37: AN | D37: State_shares_nonroad col AN: passenger rail DIESEL state SHARE (APTA-derived, normalized; AL/AM are raw train counts).
A38: nonroad_shares | B38: col_psgr_rail_elec | C38: AO | D38: State_shares_nonroad col AO: passenger rail ELECTRIC state SHARE (APTA-derived, normalized; AL/AM are raw train counts).
A39: nonroad_shares | B39: col_state_frgt_rail | C39: AR | D39: State_shares_nonroad col AR: state ABBR for freight rail.
A40: nonroad_shares | B40: col_frgt_rail | C40: AS | D40: State_shares_nonroad col AS: freight rail state share (AAR carloads).
A41: nonroad_shares | B41: col_state_psgr_ship | C41: AV | D41: State_shares_nonroad col AV: state ABBR for passenger ships.
A42: nonroad_shares | B42: col_psgr_ships | C42: AW | D42: State_shares_nonroad col AW: passenger ships state share (BTS recreational boats).
A43: nonroad_shares | B43: col_state_frgt_ship | C43: AZ | D43: State_shares_nonroad col AZ: state ABBR for freight ships.
A44: nonroad_shares | B44: col_frgt_ships | C44: BA | D44: State_shares_nonroad col BA: freight ships state share (BTS port tonnage).
A45: us_totals | B45: row_LDVs | C45: 2 | D45: US_syvbt_*_totals row 2 = LDVs.
A46: us_totals | B46: row_HDVs | C46: 3 | D46: US_syvbt_*_totals row 3 = HDVs.
A47: us_totals | B47: row_aircraft | C47: 4 | D47: US_syvbt_*_totals row 4 = aircraft.
A48: us_totals | B48: row_rail | C48: 5 | D48: US_syvbt_*_totals row 5 = rail.
A49: us_totals | B49: row_ships | C49: 6 | D49: US_syvbt_*_totals row 6 = ships.
...

Sheet SSYVbT-passenger-LDVs
A1: passenger LDVs — vehicles 2024 (v2 direct-state)
A2: State | B2: battery electric vehicle | C2: natural gas vehicle | D2: gasoline vehicle | E2: diesel vehicle | F2: plugin hybrid vehicle | G2: LPG vehicle | H2: hydrogen vehicle
A3: =State_lookup!B2 -> Alabama | B3: =ROUND(AFDC_state_fuels_lookup!C3, 0) -> 17500 | C3: =ROUND(AFDC_state_fuels_lookup!E3, 0) -> 100 | D3: =ROUND(MAX(0, State_lookup!O2 - B3-C3-E3-F3-G3-H3), 0) -> 5181815 | E3: =ROUND(AFDC_state_fuels_lookup!G3, 0) -> 28594 | F3: =ROUND(AFDC_state_fuels_lookup!D3, 0) -> 6800 | G3: =ROUND(AFDC_state_fuels_lookup!H3, 0) -> 100 | H3: =ROUND(AFDC_state_fuels_lookup!I3, 0) -> 0
A4: =State_lookup!B3 -> Arizona | B4: =ROUND(AFDC_state_fuels_lookup!C4, 0) -> 111200 | C4: =ROUND(AFDC_state_fuels_lookup!E4, 0) -> 500 | D4: =ROUND(MAX(0, State_lookup!O3 - B4-C4-E4-F4-G4-H4), 0) -> 5865636 | E4: =ROUND(AFDC_state_fuels_lookup!G4, 0) -> 42056 | F4: =ROUND(AFDC_state_fuels_lookup!D4, 0) -> 29300 | G4: =ROUND(AFDC_state_fuels_lookup!H4, 0) -> 700 | H4: =ROUND(AFDC_state_fuels_lookup!I4, 0) -> 0
A5: =State_lookup!B4 -> Arkansas | B5: =ROUND(AFDC_state_fuels_lookup!C5, 0) -> 9500 | C5: =ROUND(AFDC_state_fuels_lookup!E5, 0) -> 200 | D5: =ROUND(MAX(0, State_lookup!O4 - B5-C5-E5-F5-G5-H5), 0) -> 3033562 | E5: =ROUND(AFDC_state_fuels_lookup!G5, 0) -> 20015 | F5: =ROUND(AFDC_state_fuels_lookup!D5, 0) -> 3800 | G5: =ROUND(AFDC_state_fuels_lookup!H5, 0) -> 0 | H5: =ROUND(AFDC_state_fuels_lookup!I5, 0) -> 0
A6: =State_lookup!B5 -> California | B6: =ROUND(AFDC_state_fuels_lookup!C6, 0) -> 1533900 | C6: =ROUND(AFDC_state_fuels_lookup!E6, 0) -> 10000 | D6: =ROUND(MAX(0, State_lookup!O5 - B6-C6-E6-F6-G6-H6), 0) -> 26563767 | E6: =ROUND(AFDC_state_fuels_lookup!G6, 0) -> 145284 | F6: =ROUND(AFDC_state_fuels_lookup!D6, 0) -> 447100 | G6: =ROUND(AFDC_state_fuels_lookup!H6, 0) -> 1500 | H6: =ROUND(AFDC_state_fuels_lookup!I6, 0) -> 16900
A7: =State_lookup!B6 -> Colorado | B7: =ROUND(AFDC_state_fuels_lookup!C7, 0) -> 127000 | C7: =ROUND(AFDC_state_fuels_lookup!E7, 0) -> 300 | D7: =ROUND(MAX(0, State_lookup!O6 - B7-C7-E7-F7-G7-H7), 0) -> 4569865 | E7: =ROUND(AFDC_state_fuels_lookup!G7, 0) -> 41915 | F7: =ROUND(AFDC_state_fuels_lookup!D7, 0) -> 48700 | G7: =ROUND(AFDC_state_fuels_lookup!H7, 0) -> 100 | H7: =ROUND(AFDC_state_fuels_lookup!I7, 0) -> 0
A8: =State_lookup!B7 -> Connecticut | B8: =ROUND(AFDC_state_fuels_lookup!C8, 0) -> 39400 | C8: =ROUND(AFDC_state_fuels_lookup!E8, 0) -> 100 | D8: =ROUND(MAX(0, State_lookup!O7 - B8-C8-E8-F8-G8-H8), 0) -> 2511877 | E8: =ROUND(AFDC_state_fuels_lookup!G8, 0) -> 8027 | F8: =ROUND(AFDC_state_fuels_lookup!D8, 0) -> 22500 | G8: =ROUND(AFDC_state_fuels_lookup!H8, 0) -> 0 | H8: =ROUND(AFDC_state_fuels_lookup!I8, 0) -> 0
A9: =State_lookup!B8 -> Delaware | B9: =ROUND(AFDC_state_fuels_lookup!C9, 0) -> 11100 | C9: =ROUND(AFDC_state_fuels_lookup!E9, 0) -> 0 | D9: =ROUND(MAX(0, State_lookup!O8 - B9-C9-E9-F9-G9-H9), 0) -> 853623 | E9: =ROUND(AFDC_state_fuels_lookup!G9, 0) -> 2967 | F9: =ROUND(AFDC_state_fuels_lookup!D9, 0) -> 4600 | G9: =ROUND(AFDC_state_fuels_lookup!H9, 0) -> 0 | H9: =ROUND(AFDC_state_fuels_lookup!I9, 0) -> 0
A10: =State_lookup!B9 -> Florida | B10: =ROUND(AFDC_state_fuels_lookup!C10, 0) -> 334800 | C10: =ROUND(AFDC_state_fuels_lookup!E10, 0) -> 400 | D10: =ROUND(MAX(0, State_lookup!O9 - B10-C10-E10-F10-G10-H10), 0) -> 17568363 | E10: =ROUND(AFDC_state_fuels_lookup!G10, 0) -> 82703 | F10: =ROUND(AFDC_state_fuels_lookup!D10, 0) -> 70400 | G10: =ROUND(AFDC_state_fuels_lookup!H10, 0) -> 100 | H10: =ROUND(AFDC_state_fuels_lookup!I10, 0) -> 0
A11: =State_lookup!B10 -> Georgia | B11: =ROUND(AFDC_state_fuels_lookup!C11, 0) -> 120000 | C11: =ROUND(AFDC_state_fuels_lookup!E11, 0) -> 300 | D11: =ROUND(MAX(0, State_lookup!O10 - B11-C11-E11-F11-G11-H11), 0) -> 8385378 | E11: =ROUND(AFDC_state_fuels_lookup!G11, 0) -> 47128 | F11: =ROUND(AFDC_state_fuels_lookup!D11, 0) -> 26400 | G11: =ROUND(AFDC_state_fuels_lookup!H11, 0) -> 200 | H11: =ROUND(AFDC_state_fuels_lookup!I11, 0) -> 0
A12: =State_lookup!B11 -> Idaho | B12: =ROUND(AFDC_state_fuels_lookup!C12, 0) -> 11000 | C12: =ROUND(AFDC_state_fuels_lookup!E12, 0) -> 100 | D12: =ROUND(MAX(0, State_lookup!O11 - B12-C12-E12-F12-G12-H12), 0) -> 1788858 | E12: =ROUND(AFDC_state_fuels_lookup!G12, 0) -> 29687 | F12: =ROUND(AFDC_state_fuels_lookup!D12, 0) -> 5600 | G12: =ROUND(AFDC_state_fuels_lookup!H12, 0) -> 100 | H12: =ROUND(AFDC_state_fuels_lookup!I12, 0) -> 0
A13: =State_lookup!B12 -> Illinois | B13: =ROUND(AFDC_state_fuels_lookup!C13, 0) -> 125500 | C13: =ROUND(AFDC_state_fuels_lookup!E13, 0) -> 300 | D13: =ROUND(MAX(0, State_lookup!O12 - B13-C13-E13-F13-G13-H13), 0) -> 9498879 | E13: =ROUND(AFDC_state_fuels_lookup!G13, 0) -> 36052 | F13: =ROUND(AFDC_state_fuels_lookup!D13, 0) -> 40400 | G13: =ROUND(AFDC_state_fuels_lookup!H13, 0) -> 0 | H13: =ROUND(AFDC_state_fuels_lookup!I13, 0) -> 0
A14: =State_lookup!B13 -> Indiana | B14: =ROUND(AFDC_state_fuels_lookup!C14, 0) -> 34600 | C14: =ROUND(AFDC_state_fuels_lookup!E14, 0) -> 300 | D14: =ROUND(MAX(0, State_lookup!O13 - B14-C14-E14-F14-G14-H14), 0) -> 5454035 | E14: =ROUND(AFDC_state_fuels_lookup!G14, 0) -> 33028 | F14: =ROUND(AFDC_state_fuels_lookup!D14, 0) -> 15300 | G14: =ROUND(AFDC_state_fuels_lookup!H14, 0) -> 0 | H14: =ROUND(AFDC_state_fuels_lookup!I14, 0) -> 0
... A50: =State_lookup!B49 -> Wyoming | B50: =ROUND(AFDC_state_fuels_lookup!C50, 0) -> 1500 | C50: =ROUND(AFDC_state_fuels_lookup!E50, 0) -> 0 | D50: =ROUND(MAX(0, State_lookup!O49 - B50-C50-E50-F50-G50-H50), 0) -> 776343 | E50: =ROUND(AFDC_state_fuels_lookup!G50, 0) -> 13077 | F50: =ROUND(AFDC_state_fuels_lookup!D50, 0) -> 1000 | G50: =ROUND(AFDC_state_fuels_lookup!H50, 0) -> 0 | H50: =ROUND(AFDC_state_fuels_lookup!I50, 0) -> 0
A51: STATE SUM | B51: =SUM(B3:B50) -> 4460300 | C51: =SUM(C3:C50) -> 23600 | D51: =SUM(D3:D50) -> 253670795 | E51: =SUM(E3:E50) -> 1553090 | F51: =SUM(F3:F50) -> 1480032 | G51: =SUM(G3:G50) -> 5700 | H51: =SUM(H3:H50) -> 16900
A52: NATIONAL (AEO) | B52: =National_totals!$C$2 -> 4769953 | C52: =National_totals!$D$2 -> 14506 | D52: =National_totals!$E$2 -> 257649823 | E52: =National_totals!$F$2 -> 1553093 | F52: =National_totals!$G$2 -> 1417825 | G52: =National_totals!$H$2 -> 13525 | H52: =National_totals!$I$2 -> 17094
A53: DELTA % (state-sum vs national) | B53: =IFERROR((B51-B52)/B52, 0) -> -0.064917411 | C53: =IFERROR((C51-C52)/C52, 0) -> 0.626913 | D53: =IFERROR((D51-D52)/D52, 0) -> -0.01544355 | E53: =IFERROR((E51-E52)/E52, 0) -> -1.9316293e-06 | F53: =IFERROR((F51-F52)/F52, 0) -> 0.043874949 | G53: =IFERROR((G51-G52)/G52, 0) -> -0.57855823 | H53: =IFERROR((H51-H52)/H52, 0) -> -0.011349011

Sheet SSYVbT-passenger-HDVs
A1: passenger HDVs — vehicles 2024 (v2 direct-state)
A2: State | B2: battery electric vehicle | C2: natural gas vehicle | D2: gasoline vehicle | E2: diesel vehicle | F2: plugin hybrid vehicle | G2: LPG vehicle | H2: hydrogen vehicle
A3: =State_lookup!B2 -> Alabama | B3: =ROUND(State_lookup!D2*(National_totals!$C$3/SUM(National_totals!$C$3:$I$3)), 0) -> 1 | C3: =ROUND(State_lookup!D2*(National_totals!$D$3/SUM(National_totals!$C$3:$I$3)), 0) -> 401 | D3: =ROUND(State_lookup!D2*(National_totals!$E$3/SUM(National_totals!$C$3:$I$3)), 0) -> 315 | E3: =ROUND(State_lookup!D2*(National_totals!$F$3/SUM(National_totals!$C$3:$I$3)), 0) -> 2505 | F3: =ROUND(State_lookup!D2*(National_totals!$G$3/SUM(National_totals!$C$3:$I$3)), 0) -> 0 | G3: =ROUND(State_lookup!D2*(National_totals!$H$3/SUM(National_totals!$C$3:$I$3)), 0) -> 147 | H3: =ROUND(State_lookup!D2*(National_totals!$I$3/SUM(National_totals!$C$3:$I$3)), 0) -> 1
A4: =State_lookup!B3 -> Arizona | B4: =ROUND(State_lookup!D3*(National_totals!$C$3/SUM(National_totals!$C$3:$I$3)), 0) -> 6 | C4: =ROUND(State_lookup!D3*(National_totals!$D$3/SUM(National_totals!$C$3:$I$3)), 0) -> 2689 | D4: =ROUND(State_lookup!D3*(National_totals!$E$3/SUM(National_totals!$C$3:$I$3)), 0) -> 2117 | E4: =ROUND(State_lookup!D3*(National_totals!$F$3/SUM(National_totals!$C$3:$I$3)), 0) -> 16816 | F4: =ROUND(State_lookup!D3*(National_totals!$G$3/SUM(National_totals!$C$3:$I$3)), 0) -> 0 | G4: =ROUND(State_lookup!D3*(National_totals!$H$3/SUM(National_totals!$C$3:$I$3)), 0) -> 985 | H4: =ROUND(State_lookup!D3*(National_totals!$I$3/SUM(National_totals!$C$3:$I$3)), 0) -> 4
A5: =State_lookup!B4 -> Arkansas | B5: =ROUND(State_lookup!D4*(National_totals!$C$3/SUM(National_totals!$C$3:$I$3)), 0) -> 3 | C5: =ROUND(State_lookup!D4*(National_totals!$D$3/SUM(National_totals!$C$3:$I$3)), 0) -> 1285 | D5: =ROUND(State_lookup!D4*(National_totals!$E$3/SUM(National_totals!$C$3:$I$3)), 0) -> 1011 | E5: =ROUND(State_lookup!D4*(National_totals!$F$3/SUM(National_totals!$C$3:$I$3)), 0) -> 8034 | F5: =ROUND(State_lookup!D4*(National_totals!$G$3/SUM(National_totals!$C$3:$I$3)), 0) -> 0 | G5: =ROUND(State_lookup!D4*(National_totals!$H$3/SUM(National_totals!$C$3:$I$3)), 0) -> 471 | H5: =ROUND(State_lookup!D4*(National_totals!$I$3/SUM(National_totals!$C$3:$I$3)), 0) -> 2
A6: =State_lookup!B5 -> California | B6: =ROUND(State_lookup!D5*(National_totals!$C$3/SUM(National_totals!$C$3:$I$3)), 0) -> 27 | C6: =ROUND(State_lookup!D5*(National_totals!$D$3/SUM(National_totals!$C$3:$I$3)), 0) -> 11443 | D6: =ROUND(State_lookup!D5*(National_totals!$E$3/SUM(National_totals!$C$3:$I$3)), 0) -> 9005 | E6: =ROUND(State_lookup!D5*(National_totals!$F$3/SUM(National_totals!$C$3:$I$3)), 0) -> 71547 | F6: =ROUND(State_lookup!D5*(National_totals!$G$3/SUM(National_totals!$C$3:$I$3)), 0) -> 0 | G6: =ROUND(State_lookup!D5*(National_totals!$H$3/SUM(National_totals!$C$3:$I$3)), 0) -> 4192 | H6: =ROUND(State_lookup!D5*(National_totals!$I$3/SUM(National_totals!$C$3:$I$3)), 0) -> 16
A7: =State_lookup!B6 -> Colorado | B7: =ROUND(State_lookup!D6*(National_totals!$C$3/SUM(National_totals!$C$3:$I$3)), 0) -> 4 | C7: =ROUND(State_lookup!D6*(National_totals!$D$3/SUM(National_totals!$C$3:$I$3)), 0) -> 1499 | D7: =ROUND(State_lookup!D6*(National_totals!$E$3/SUM(National_totals!$C$3:$I$3)), 0) -> 1179 | E7: =ROUND(State_lookup!D6*(National_totals!$F$3/SUM(National_totals!$C$3:$I$3)), 0) -> 9370 | F7: =ROUND(State_lookup!D6*(National_totals!$G$3/SUM(National_totals!$C$3:$I$3)), 0) -> 0 | G7: =ROUND(State_lookup!D6*(National_totals!$H$3/SUM(National_totals!$C$3:$I$3)), 0) -> 549 | H7: =ROUND(State_lookup!D6*(National_totals!$I$3/SUM(National_totals!$C$3:$I$3)), 0) -> 2
A8: =State_lookup!B7 -> Connecticut | B8: =ROUND(State_lookup!D7*(National_totals!$C$3/SUM(National_totals!$C$3:$I$3)), 0) -> 3 | C8: =ROUND(State_lookup!D7*(National_totals!$D$3/SUM(National_totals!$C$3:$I$3)), 0) -> 1176 | D8: =ROUND(State_lookup!D7*(National_totals!$E$3/SUM(National_totals!$C$3:$I$3)), 0) -> 925 | E8: =ROUND(State_lookup!D7*(National_totals!$F$3/SUM(National_totals!$C$3:$I$3)), 0) -> 7352 | F8: =ROUND(State_lookup!D7*(National_totals!$G$3/SUM(National_totals!$C$3:$I$3)), 0) -> 0 | G8: =ROUND(State_lookup!D7*(National_totals!$H$3/SUM(National_totals!$C$3:$I$3)), 0) -> 431 | H8: =ROUND(State_lookup!D7*(National_totals!$I$3/SUM(National_totals!$C$3:$I$3)), 0) -> 2
A9: =State_lookup!B8 -> Delaware | B9: =ROUND(State_lookup!D8*(National_totals!$C$3/SUM(National_totals!$C$3:$I$3)), 0) -> 1 | C9: =ROUND(State_lookup!D8*(National_totals!$D$3/SUM(National_totals!$C$3:$I$3)), 0) -> 414 | D9: =ROUND(State_lookup!D8*(National_totals!$E$3/SUM(National_totals!$C$3:$I$3)), 0) -> 326 | E9: =ROUND(State_lookup!D8*(National_totals!$F$3/SUM(National_totals!$C$3:$I$3)), 0) -> 2590 | F9: =ROUND(State_lookup!D8*(National_totals!$G$3/SUM(National_totals!$C$3:$I$3)), 0) -> 0 | G9: =ROUND(State_lookup!D8*(National_totals!$H$3/SUM(National_totals!$C$3:$I$3)), 0) -> 152 | H9: =ROUND(State_lookup!D8*(National_totals!$I$3/SUM(National_totals!$C$3:$I$3)), 0) -> 1
A10: =State_lookup!B9 -> Florida | B10: =ROUND(State_lookup!D9*(National_totals!$C$3/SUM(National_totals!$C$3:$I$3)), 0) -> 16 | C10: =ROUND(State_lookup!D9*(National_totals!$D$3/SUM(National_totals!$C$3:$I$3)), 0) -> 6834 | D10: =ROUND(State_lookup!D9*(National_totals!$E$3/SUM(National_totals!$C$3:$I$3)), 0) -> 5378 | E10: =ROUND(State_lookup!D9*(National_totals!$F$3/SUM(National_totals!$C$3:$I$3)), 0) -> 42728 | F10: =ROUND(State_lookup!D9*(National_totals!$G$3/SUM(National_totals!$C$3:$I$3)), 0) -> 0 | G10: =ROUND(State_lookup!D9*(National_totals!$H$3/SUM(National_totals!$C$3:$I$3)), 0) -> 2503 | H10: =ROUND(State_lookup!D9*(National_totals!$I$3/SUM(National_totals!$C$3:$I$3)), 0) -> 9
A11: =State_lookup!B10 -> Georgia | B11: =ROUND(State_lookup!D10*(National_totals!$C$3/SUM(National_totals!$C$3:$I$3)), 0) -> 11 | C11: =ROUND(State_lookup!D10*(National_totals!$D$3/SUM(National_totals!$C$3:$I$3)), 0) -> 4683 | D11: =ROUND(State_lookup!D10*(National_totals!$E$3/SUM(National_totals!$C$3:$I$3)), 0) -> 3685 | E11: =ROUND(State_lookup!D10*(National_totals!$F$3/SUM(National_totals!$C$3:$I$3)), 0) -> 29280 | F11: =ROUND(State_lookup!D10*(National_totals!$G$3/SUM(National_totals!$C$3:$I$3)), 0) -> 0 | G11: =ROUND(State_lookup!D10*(National_totals!$H$3/SUM(National_totals!$C$3:$I$3)), 0) -> 1716 | H11: =ROUND(State_lookup!D10*(National_totals!$I$3/SUM(National_totals!$C$3:$I$3)), 0) -> 6
A12: =State_lookup!B11 -> Idaho | B12: =ROUND(State_lookup!D11*(National_totals!$C$3/SUM(National_totals!$C$3:$I$3)), 0) -> 1 | C12: =ROUND(State_lookup!D11*(National_totals!$D$3/SUM(National_totals!$C$3:$I$3)), 0) -> 485 | D12: =ROUND(State_lookup!D11*(National_totals!$E$3/SUM(National_totals!$C$3:$I$3)), 0) -> 382 | E12: =ROUND(State_lookup!D11*(National_totals!$F$3/SUM(National_totals!$C$3:$I$3)), 0) -> 3035 | F12: =ROUND(State_lookup!D11*(National_totals!$G$3/SUM(National_totals!$C$3:$I$3)), 0) -> 0 | G12: =ROUND(State_lookup!D11*(National_totals!$H$3/SUM(National_totals!$C$3:$I$3)), 0) -> 178 | H12: =ROUND(State_lookup!D11*(National_totals!$I$3/SUM(National_totals!$C$3:$I$3)), 0) -> 1
A13: =State_lookup!B12 -> Illinois | B13: =ROUND(State_lookup!D12*(National_totals!$C$3/SUM(National_totals!$C$3:$I$3)), 0) -> 11 | C13: =ROUND(State_lookup!D12*(National_totals!$D$3/SUM(National_totals!$C$3:$I$3)), 0) -> 4659 | D13: =ROUND(State_lookup!D12*(National_totals!$E$3/SUM(National_totals!$C$3:$I$3)), 0) -> 3667 | E13: =ROUND(State_lookup!D12*(National_totals!$F$3/SUM(National_totals!$C$3:$I$3)), 0) -> 29133 | F13: =ROUND(State_lookup!D12*(National_totals!$G$3/SUM(National_totals!$C$3:$I$3)), 0) -> 0 | G13: =ROUND(State_lookup!D12*(National_totals!$H$3/SUM(National_totals!$C$3:$I$3)), 0) -> 1707 | H13: =ROUND(State_lookup!D12*(National_totals!$I$3/SUM(National_totals!$C$3:$I$3)), 0) -> 6
A14: =State_lookup!B13 -> Indiana | B14: =ROUND(State_lookup!D13*(National_totals!$C$3/SUM(National_totals!$C$3:$I$3)), 0) -> 9 | C14: =ROUND(State_lookup!D13*(National_totals!$D$3/SUM(National_totals!$C$3:$I$3)), 0) -> 3848 | D14: =ROUND(State_lookup!D13*(National_totals!$E$3/SUM(National_totals!$C$3:$I$3)), 0) -> 3028 | E14: =ROUND(State_lookup!D13*(National_totals!$F$3/SUM(National_totals!$C$3:$I$3)), 0) -> 24060 | F14: =ROUND(State_lookup!D13*(National_totals!$G$3/SUM(National_totals!$C$3:$I$3)), 0) -> 0 | G14: =ROUND(State_lookup!D13*(National_totals!$H$3/SUM(National_totals!$C$3:$I$3)), 0) -> 1410 | H14: =ROUND(State_lookup!D13*(National_totals!$I$3/SUM(National_totals!$C$3:$I$3)), 0) -> 5
... A50: =State_lookup!B49 -> Wyoming | B50: =ROUND(State_lookup!D49*(National_totals!$C$3/SUM(National_totals!$C$3:$I$3)), 0) -> 1 | C50: =ROUND(State_lookup!D49*(National_totals!$D$3/SUM(National_totals!$C$3:$I$3)), 0) -> 232 | D50: =ROUND(State_lookup!D49*(National_totals!$E$3/SUM(National_totals!$C$3:$I$3)), 0) -> 183 | E50: =ROUND(State_lookup!D49*(National_totals!$F$3/SUM(National_totals!$C$3:$I$3)), 0) -> 1452 | F50: =ROUND(State_lookup!D49*(National_totals!$G$3/SUM(National_totals!$C$3:$I$3)), 0) -> 0 | G50: =ROUND(State_lookup!D49*(National_totals!$H$3/SUM(National_totals!$C$3:$I$3)), 0) -> 85 | H50: =ROUND(State_lookup!D49*(National_totals!$I$3/SUM(National_totals!$C$3:$I$3)), 0) -> 0
A51: STATE SUM | B51: =SUM(B3:B50) -> 301 | C51: =SUM(C3:C50) -> 128421 | D51: =SUM(D3:D50) -> 101067 | E51: =SUM(E3:E50) -> 802956 | F51: =SUM(F3:F50) -> 0 | G51: =SUM(G3:G50) -> 47045 | H51: =SUM(H3:H50) -> 172
A52: NATIONAL (AEO) | B52: =National_totals!$C$3 -> 300 | C52: =National_totals!$D$3 -> 128402 | D52: =National_totals!$E$3 -> 101051 | E52: =National_totals!$F$3 -> 802832 | F52: =National_totals!$G$3 -> 0 | G52: =National_totals!$H$3 -> 47038 | H52: =National_totals!$I$3 -> 174
A53: DELTA % (state-sum vs national) | B53: =IFERROR((B51-B52)/B52, 0) -> 0.0033333333 | C53: =IFERROR((C51-C52)/C52, 0) -> 0.00014797277 | D53: =IFERROR((D51-D52)/D52, 0) -> 0.00015833589 | E53: =IFERROR((E51-E52)/E52, 0) -> 0.00015445324 | F53: =IFERROR((F51-F52)/F52, 0) -> 0 | G53: =IFERROR((G51-G52)/G52, 0) -> 0.00014881585 | H53: =IFERROR((H51-H52)/H52, 0) -> -0.011494253

Sheet SSYVbT-passenger-aircraft
A1: passenger aircraft — vehicles 2024 (v2 direct-state)
A2: State | B2: battery electric vehicle | C2: natural gas vehicle | D2: gasoline vehicle | E2: diesel vehicle | F2: plugin hybrid vehicle | G2: LPG vehicle | H2: hydrogen vehicle
A3: =State_lookup!B2 -> Alabama | B3: =IFERROR(ROUND(State_lookup!H2/SUM(State_lookup!H2:H49)*National_totals!$C$4, 0), 0) -> 0 | C3: =IFERROR(ROUND(State_lookup!H2/SUM(State_lookup!H2:H49)*National_totals!$D$4, 0), 0) -> 0 | D3: =IFERROR(ROUND(State_lookup!H2/SUM(State_lookup!H2:H49)*National_totals!$E$4, 0), 0) -> 0 | E3: =IFERROR(ROUND(MAX(State_lookup!H2/SUM(State_lookup!H2:H49)*National_totals!$F$4, Keys!$C$59), 0), 0) -> 24 | F3: =IFERROR(ROUND(State_lookup!H2/SUM(State_lookup!H2:H49)*National_totals!$G$4, 0), 0) -> 0 | G3: =IFERROR(ROUND(State_lookup!H2/SUM(State_lookup!H2:H49)*National_totals!$H$4, 0), 0) -> 0 | H3: =IFERROR(ROUND(State_lookup!H2/SUM(State_lookup!H2:H49)*National_totals!$I$4, 0), 0) -> 0
A4: =State_lookup!B3 -> Arizona | B4: =IFERROR(ROUND(State_lookup!H3/SUM(State_lookup!H2:H49)*National_totals!$C$4, 0), 0) -> 0 | C4: =IFERROR(ROUND(State_lookup!H3/SUM(State_lookup!H2:H49)*National_totals!$D$4, 0), 0) -> 0 | D4: =IFERROR(ROUND(State_lookup!H3/SUM(State_lookup!H2:H49)*National_totals!$E$4, 0), 0) -> 0 | E4: =IFERROR(ROUND(MAX(State_lookup!H3/SUM(State_lookup!H2:H49)*National_totals!$F$4, Keys!$C$59), 0), 0) -> 194 | F4: =IFERROR(ROUND(State_lookup!H3/SUM(State_lookup!H2:H49)*National_totals!$G$4, 0), 0) -> 0 | G4: =IFERROR(ROUND(State_lookup!H3/SUM(State_lookup!H2:H49)*National_totals!$H$4, 0), 0) -> 0 | H4: =IFERROR(ROUND(State_lookup!H3/SUM(State_lookup!H2:H49)*National_totals!$I$4, 0), 0) -> 0
A5: =State_lookup!B4 -> Arkansas | B5: =IFERROR(ROUND(State_lookup!H4/SUM(State_lookup!H2:H49)*National_totals!$C$4, 0), 0) -> 0 | C5: =IFERROR(ROUND(State_lookup!H4/SUM(State_lookup!H2:H49)*National_totals!$D$4, 0), 0) -> 0 | D5: =IFERROR(ROUND(State_lookup!H4/SUM(State_lookup!H2:H49)*National_totals!$E$4, 0), 0) -> 0 | E5: =IFERROR(ROUND(MAX(State_lookup!H4/SUM(State_lookup!H2:H49)*National_totals!$F$4, Keys!$C$59), 0), 0) -> 24 | F5: =IFERROR(ROUND(State_lookup!H4/SUM(State_lookup!H2:H49)*National_totals!$G$4, 0), 0) -> 0 | G5: =IFERROR(ROUND(State_lookup!H4/SUM(State_lookup!H2:H49)*National_totals!$H$4, 0), 0) -> 0 | H5: =IFERROR(ROUND(State_lookup!H4/SUM(State_lookup!H2:H49)*National_totals!$I$4, 0), 0) -> 0
A6: =State_lookup!B5 -> California | B6: =IFERROR(ROUND(State_lookup!H5/SUM(State_lookup!H2:H49)*National_totals!$C$4, 0), 0) -> 0 | C6: =IFERROR(ROUND(State_lookup!H5/SUM(State_lookup!H2:H49)*National_totals!$D$4, 0), 0) -> 0 | D6: =IFERROR(ROUND(State_lookup!H5/SUM(State_lookup!H2:H49)*National_totals!$E$4, 0), 0) -> 0 | E6: =IFERROR(ROUND(MAX(State_lookup!H5/SUM(State_lookup!H2:H49)*National_totals!$F$4, Keys!$C$59), 0), 0) -> 903 | F6: =IFERROR(ROUND(State_lookup!H5/SUM(State_lookup!H2:H49)*National_totals!$G$4, 0), 0) -> 0 | G6: =IFERROR(ROUND(State_lookup!H5/SUM(State_lookup!H2:H49)*National_totals!$H$4, 0), 0) -> 0 | H6: =IFERROR(ROUND(State_lookup!H5/SUM(State_lookup!H2:H49)*National_totals!$I$4, 0), 0) -> 0
A7: =State_lookup!B6 -> Colorado | B7: =IFERROR(ROUND(State_lookup!H6/SUM(State_lookup!H2:H49)*National_totals!$C$4, 0), 0) -> 0 | C7: =IFERROR(ROUND(State_lookup!H6/SUM(State_lookup!H2:H49)*National_totals!$D$4, 0), 0) -> 0 | D7: =IFERROR(ROUND(State_lookup!H6/SUM(State_lookup!H2:H49)*National_totals!$E$4, 0), 0) -> 0 | E7: =IFERROR(ROUND(MAX(State_lookup!H6/SUM(State_lookup!H2:H49)*National_totals!$F$4, Keys!$C$59), 0), 0) -> 267 | F7: =IFERROR(ROUND(State_lookup!H6/SUM(State_lookup!H2:H49)*National_totals!$G$4, 0), 0) -> 0 | G7: =IFERROR(ROUND(State_lookup!H6/SUM(State_lookup!H2:H49)*National_totals!$H$4, 0), 0) -> 0 | H7: =IFERROR(ROUND(State_lookup!H6/SUM(State_lookup!H2:H49)*National_totals!$I$4, 0), 0) -> 0
A8: =State_lookup!B7 -> Connecticut | B8: =IFERROR(ROUND(State_lookup!H7/SUM(State_lookup!H2:H49)*National_totals!$C$4, 0), 0) -> 0 | C8: =IFERROR(ROUND(State_lookup!H7/SUM(State_lookup!H2:H49)*National_totals!$D$4, 0), 0) -> 0 | D8: =IFERROR(ROUND(State_lookup!H7/SUM(State_lookup!H2:H49)*National_totals!$E$4, 0), 0) -> 0 | E8: =IFERROR(ROUND(MAX(State_lookup!H7/SUM(State_lookup!H2:H49)*National_totals!$F$4, Keys!$C$59), 0), 0) -> 25 | F8: =IFERROR(ROUND(State_lookup!H7/SUM(State_lookup!H2:H49)*National_totals!$G$4, 0), 0) -> 0 | G8: =IFERROR(ROUND(State_lookup!H7/SUM(State_lookup!H2:H49)*National_totals!$H$4, 0), 0) -> 0 | H8: =IFERROR(ROUND(State_lookup!H7/SUM(State_lookup!H2:H49)*National_totals!$I$4, 0), 0) -> 0
A9: =State_lookup!B8 -> Delaware | B9: =IFERROR(ROUND(State_lookup!H8/SUM(State_lookup!H2:H49)*National_totals!$C$4, 0), 0) -> 0 | C9: =IFERROR(ROUND(State_lookup!H8/SUM(State_lookup!H2:H49)*National_totals!$D$4, 0), 0) -> 0 | D9: =IFERROR(ROUND(State_lookup!H8/SUM(State_lookup!H2:H49)*National_totals!$E$4, 0), 0) -> 0 | E9: =IFERROR(ROUND(MAX(State_lookup!H8/SUM(State_lookup!H2:H49)*National_totals!$F$4, Keys!$C$59), 0), 0) -> 24 | F9: =IFERROR(ROUND(State_lookup!H8/SUM(State_lookup!H2:H49)*National_totals!$G$4, 0), 0) -> 0 | G9: =IFERROR(ROUND(State_lookup!H8/SUM(State_lookup!H2:H49)*National_totals!$H$4, 0), 0) -> 0 | H9: =IFERROR(ROUND(State_lookup!H8/SUM(State_lookup!H2:H49)*National_totals!$I$4, 0), 0) -> 0
A10: =State_lookup!B9 -> Florida | B10: =IFERROR(ROUND(State_lookup!H9/SUM(State_lookup!H2:H49)*National_totals!$C$4, 0), 0) -> 0 | C10: =IFERROR(ROUND(State_lookup!H9/SUM(State_lookup!H2:H49)*National_totals!$D$4, 0), 0) -> 0 | D10: =IFERROR(ROUND(State_lookup!H9/SUM(State_lookup!H2:H49)*National_totals!$E$4, 0), 0) -> 0 | E10: =IFERROR(ROUND(MAX(State_lookup!H9/SUM(State_lookup!H2:H49)*National_totals!$F$4, Keys!$C$59), 0), 0) -> 717 | F10: =IFERROR(ROUND(State_lookup!H9/SUM(State_lookup!H2:H49)*National_totals!$G$4, 0), 0) -> 0 | G10: =IFERROR(ROUND(State_lookup!H9/SUM(State_lookup!H2:H49)*National_totals!$H$4, 0), 0) -> 0 | H10: =IFERROR(ROUND(State_lookup!H9/SUM(State_lookup!H2:H49)*National_totals!$I$4, 0), 0) -> 0
A11: =State_lookup!B10 -> Georgia | B11: =IFERROR(ROUND(State_lookup!H10/SUM(State_lookup!H2:H49)*National_totals!$C$4, 0), 0) -> 0 | C11: =IFERROR(ROUND(State_lookup!H10/SUM(State_lookup!H2:H49)*National_totals!$D$4, 0), 0) -> 0 | D11: =IFERROR(ROUND(State_lookup!H10/SUM(State_lookup!H2:H49)*National_totals!$E$4, 0), 0) -> 0 | E11: =IFERROR(ROUND(MAX(State_lookup!H10/SUM(State_lookup!H2:H49)*National_totals!$F$4, Keys!$C$59), 0), 0) -> 415 | F11: =IFERROR(ROUND(State_lookup!H10/SUM(State_lookup!H2:H49)*National_totals!$G$4, 0), 0) -> 0 | G11: =IFERROR(ROUND(State_lookup!H10/SUM(State_lookup!H2:H49)*National_totals!$H$4, 0), 0) -> 0 | H11: =IFERROR(ROUND(State_lookup!H10/SUM(State_lookup!H2:H49)*National_totals!$I$4, 0), 0) -> 0
A12: =State_lookup!B11 -> Idaho | B12: =IFERROR(ROUND(State_lookup!H11/SUM(State_lookup!H2:H49)*National_totals!$C$4, 0), 0) -> 0 | C12: =IFERROR(ROUND(State_lookup!H11/SUM(State_lookup!H2:H49)*National_totals!$D$4, 0), 0) -> 0 | D12: =IFERROR(ROUND(State_lookup!H11/SUM(State_lookup!H2:H49)*National_totals!$E$4, 0), 0) -> 0 | E12: =IFERROR(ROUND(MAX(State_lookup!H11/SUM(State_lookup!H2:H49)*National_totals!$F$4, Keys!$C$59), 0), 0) -> 24 | F12: =IFERROR(ROUND(State_lookup!H11/SUM(State_lookup!H2:H49)*National_totals!$G$4, 0), 0) -> 0 | G12: =IFERROR(ROUND(State_lookup!H11/SUM(State_lookup!H2:H49)*National_totals!$H$4, 0), 0) -> 0 | H12: =IFERROR(ROUND(State_lookup!H11/SUM(State_lookup!H2:H49)*National_totals!$I$4, 0), 0) -> 0
A13: =State_lookup!B12 -> Illinois | B13: =IFERROR(ROUND(State_lookup!H12/SUM(State_lookup!H2:H49)*National_totals!$C$4, 0), 0) -> 0 | C13: =IFERROR(ROUND(State_lookup!H12/SUM(State_lookup!H2:H49)*National_totals!$D$4, 0), 0) -> 0 | D13: =IFERROR(ROUND(State_lookup!H12/SUM(State_lookup!H2:H49)*National_totals!$E$4, 0), 0) -> 0 | E13: =IFERROR(ROUND(MAX(State_lookup!H12/SUM(State_lookup!H2:H49)*National_totals!$F$4, Keys!$C$59), 0), 0) -> 392 | F13: =IFERROR(ROUND(State_lookup!H12/SUM(State_lookup!H2:H49)*National_totals!$G$4, 0), 0) -> 0 | G13: =IFERROR(ROUND(State_lookup!H12/SUM(State_lookup!H2:H49)*National_totals!$H$4, 0), 0) -> 0 | H13: =IFERROR(ROUND(State_lookup!H12/SUM(State_lookup!H2:H49)*National_totals!$I$4, 0), 0) -> 0
A14: =State_lookup!B13 -> Indiana | B14: =IFERROR(ROUND(State_lookup!H13/SUM(State_lookup!H2:H49)*National_totals!$C$4, 0), 0) -> 0 | C14: =IFERROR(ROUND(State_lookup!H13/SUM(State_lookup!H2:H49)*National_totals!$D$4, 0), 0) -> 0 | D14: =IFERROR(ROUND(State_lookup!H13/SUM(State_lookup!H2:H49)*National_totals!$E$4, 0), 0) -> 0 | E14: =IFERROR(ROUND(MAX(State_lookup!H13/SUM(State_lookup!H2:H49)*National_totals!$F$4, Keys!$C$59), 0), 0) -> 43 | F14: =IFERROR(ROUND(State_lookup!H13/SUM(State_lookup!H2:H49)*National_totals!$G$4, 0), 0) -> 0 | G14: =IFERROR(ROUND(State_lookup!H13/SUM(State_lookup!H2:H49)*National_totals!$H$4, 0), 0) -> 0 | H14: =IFERROR(ROUND(State_lookup!H13/SUM(State_lookup!H2:H49)*National_totals!$I$4, 0), 0) -> 0
A15: =State_lookup!B14 -> Iowa | B15: =IFERROR(ROUND(State_lookup!H14/SUM(State_lookup!H2:H49)*National_totals!$C$4, 0), 0) -> 0 | C15: =IFERROR(ROUND(State_lookup!H14/SUM(State_lookup!H2:H49)*National_totals!$D$4, 0), 0) -> 0 | D15: =IFERROR(ROUND(State_lookup!H14/SUM(State_lookup!H2:H49)*National_totals!$E$4, 0), 0) -> 0 | E15: =IFERROR(ROUND(MAX(State_lookup!H14/SUM(State_lookup!H2:H49)*National_totals!$F$4, Keys!$C$59), 0), 0) -> 24 | F15: =IFERROR(ROUND(State_lookup!H14/SUM(State_lookup!H2:H49)*National_totals!$G$4, 0), 0) -> 0 | G15: =IFERROR(ROUND(State_lookup!H14/SUM(State_lookup!H2:H49)*National_totals!$H$4, 0), 0) -> 0 | H15: =IFERROR(ROUND(State_lookup!H14/SUM(State_lookup!H2:H49)*National_totals!$I$4, 0), 0) -> 0
A16: =State_lookup!B15 -> Kansas | B16: =IFERROR(ROUND(State_lookup!H15/SUM(State_lookup!H2:H49)*National_totals!$C$4, 0), 0) -> 0 | C16: =IFERROR(ROUND(State_lookup!H15/SUM(State_lookup!H2:H49)*National_totals!$D$4, 0), 0) -> 0 | D16: =IFERROR(ROUND(State_lookup!H15/SUM(State_lookup!H2:H49)*National_totals!$E$4, 0), 0) -> 0 | E16: =IFERROR(ROUND(MAX(State_lookup!H15/SUM(State_lookup!H2:H49)*National_totals!$F$4, Keys!$C$59), 0), 0) -> 24 | F16: =IFERROR(ROUND(State_lookup!H15/SUM(State_lookup!H2:H49)*National_totals!$G$4, 0), 0) -> 0 | G16: =IFERROR(ROUND(State_lookup!H15/SUM(State_lookup!H2:H49)*National_totals!$H$4, 0), 0) -> 0 | H16: =IFERROR(ROUND(State_lookup!H15/SUM(State_lookup!H2:H49)*National_totals!$I$4, 0), 0) -> 0
A17: =State_lookup!B16 -> Kentucky | B17: =IFERROR(ROUND(State_lookup!H16/SUM(State_lookup!H2:H49)*National_totals!$C$4, 0), 0) -> 0 | C17: =IFERROR(ROUND(State_lookup!H16/SUM(State_lookup!H2:H49)*National_totals!$D$4, 0), 0) -> 0 | D17: =IFERROR(ROUND(State_lookup!H16/SUM(State_lookup!H2:H49)*National_totals!$E$4, 0), 0) -> 0 | E17: =IFERROR(ROUND(MAX(State_lookup!H16/SUM(State_lookup!H2:H49)*National_totals!$F$4, Keys!$C$59), 0), 0) -> 54 | F17: =IFERROR(ROUND(State_lookup!H16/SUM(State_lookup!H2:H49)*National_totals!$G$4, 0), 0) -> 0 | G17: =IFERROR(ROUND(State_lookup!H16/SUM(State_lookup!H2:H49)*National_totals!$H$4, 0), 0) -> 0 | H17: =IFERROR(ROUND(State_lookup!H16/SUM(State_lookup!H2:H49)*National_totals!$I$4, 0), 0) -> 0
A18: =State_lookup!B17 -> Louisiana | B18: =IFERROR(ROUND(State_lookup!H17/SUM(State_lookup!H2:H49)*National_totals!$C$4, 0), 0) -> 0 | C18: =IFERROR(ROUND(State_lookup!H17/SUM(State_lookup!H2:H49)*National_totals!$D$4, 0), 0) -> 0 | D18: =IFERROR(ROUND(State_lookup!H17/SUM(State_lookup!H2:H49)*National_totals!$E$4, 0), 0) -> 0 | E18: =IFERROR(ROUND(MAX(State_lookup!H17/SUM(State_lookup!H2:H49)*National_totals!$F$4, Keys!$C$59), 0), 0) -> 61 | F18: =IFERROR(ROUND(State_lookup!H17/SUM(State_lookup!H2:H49)*National_totals!$G$4, 0), 0) -> 0 | G18: =IFERROR(ROUND(State_lookup!H17/SUM(State_lookup!H2:H49)*National_totals!$H$4, 0), 0) -> 0 | H18: =IFERROR(ROUND(State_lookup!H17/SUM(State_lookup!H2:H49)*National_totals!$I$4, 0), 0) -> 0
A19: =State_lookup!B18 -> Maine | B19: =IFERROR(ROUND(State_lookup!H18/SUM(State_lookup!H2:H49)*National_totals!$C$4, 0), 0) -> 0 | C19: =IFERROR(ROUND(State_lookup!H18/SUM(State_lookup!H2:H49)*National_totals!$D$4, 0), 0) -> 0 | D19: =IFERROR(ROUND(State_lookup!H18/SUM(State_lookup!H2:H49)*National_totals!$E$4, 0), 0) -> 0 | E19: =IFERROR(ROUND(MAX(State_lookup!H18/SUM(State_lookup!H2:H49)*National_totals!$F$4, Keys!$C$59), 0), 0) -> 24 | F19: =IFERROR(ROUND(State_lookup!H18/SUM(State_lookup!H2:H49)*National_totals!$G$4, 0), 0) -> 0 | G19: =IFERROR(ROUND(State_lookup!H18/SUM(State_lookup!H2:H49)*National_totals!$H$4, 0), 0) -> 0 | H19: =IFERROR(ROUND(State_lookup!H18/SUM(State_lookup!H2:H49)*National_totals!$I$4, 0), 0) -> 0
A20: =State_lookup!B19 -> Maryland | B20: =IFERROR(ROUND(State_lookup!H19/SUM(State_lookup!H2:H49)*National_totals!$C$4, 0), 0) -> 0 | C20: =IFERROR(ROUND(State_lookup!H19/SUM(State_lookup!H2:H49)*National_totals!$D$4, 0), 0) -> 0 | D20: =IFERROR(ROUND(State_lookup!H19/SUM(State_lookup!H2:H49)*National_totals!$E$4, 0), 0) -> 0 | E20: =IFERROR(ROUND(MAX(State_lookup!H19/SUM(State_lookup!H2:H49)*National_totals!$F$4, Keys!$C$59), 0), 0) -> 100 | F20: =IFERROR(ROUND(State_lookup!H19/SUM(State_lookup!H2:H49)*National_totals!$G$4, 0), 0) -> 0 | G20: =IFERROR(ROUND(State_lookup!H19/SUM(State_lookup!H2:H49)*National_totals!$H$4, 0), 0) -> 0 | H20: =IFERROR(ROUND(State_lookup!H19/SUM(State_lookup!H2:H49)*National_totals!$I$4, 0), 0) -> 0
A21: =State_lookup!B20 -> Massachusetts | B21: =IFERROR(ROUND(State_lookup!H20/SUM(State_lookup!H2:H49)*National_totals!$C$4, 0), 0) -> 0 | C21: =IFERROR(ROUND(State_lookup!H20/SUM(State_lookup!H2:H49)*National_totals!$D$4, 0), 0) -> 0 | D21: =IFERROR(ROUND(State_lookup!H20/SUM(State_lookup!H2:H49)*National_totals!$E$4, 0), 0) -> 0 | E21: =IFERROR(ROUND(MAX(State_lookup!H20/SUM(State_lookup!H2:H49)*National_totals!$F$4, Keys!$C$59), 0), 0) -> 157 | F21: =IFERROR(ROUND(State_lookup!H20/SUM(State_lookup!H2:H49)*National_totals!$G$4, 0), 0) -> 0 | G21: =IFERROR(ROUND(State_lookup!H20/SUM(State_lookup!H2:H49)*National_totals!$H$4, 0), 0) -> 0 | H21: =IFERROR(ROUND(State_lookup!H20/SUM(State_lookup!H2:H49)*National_totals!$I$4, 0), 0) -> 0
A22: =State_lookup!B21 -> Michigan | B22: =IFERROR(ROUND(State_lookup!H21/SUM(State_lookup!H2:H49)*National_totals!$C$4, 0), 0) -> 0 | C22: =IFERROR(ROUND(State_lookup!H21/SUM(State_lookup!H2:H49)*National_totals!$D$4, 0), 0) -> 0 | D22: =IFERROR(ROUND(State_lookup!H21/SUM(State_lookup!H2:H49)*National_totals!$E$4, 0), 0) -> 0 | E22: =IFERROR(ROUND(MAX(State_lookup!H21/SUM(State_lookup!H2:H49)*National_totals!$F$4, Keys!$C$59), 0), 0) -> 159 | F22: =IFERROR(ROUND(State_lookup!H21/SUM(State_lookup!H2:H49)*National_totals!$G$4, 0), 0) -> 0 | G22: =IFERROR(ROUND(State_lookup!H21/SUM(State_lookup!H2:H49)*National_totals!$H$4, 0), 0) -> 0 | H22: =IFERROR(ROUND(State_lookup!H21/SUM(State_lookup!H2:H49)*National_totals!$I$4, 0), 0) -> 0
A23: =State_lookup!B22 -> Minnesota | B23: =IFERROR(ROUND(State_lookup!H22/SUM(State_lookup!H2:H49)*National_totals!$C$4, 0), 0) -> 0 | C23: =IFERROR(ROUND(State_lookup!H22/SUM(State_lookup!H2:H49)*National_totals!$D$4, 0), 0) -> 0 | D23: =IFERROR(ROUND(State_lookup!H22/SUM(State_lookup!H2:H49)*National_totals!$E$4, 0), 0) -> 0 | E23: =IFERROR(ROUND(MAX(State_lookup!H22/SUM(State_lookup!H2:H49)*National_totals!$F$4, Keys!$C$59), 0), 0) -> 147 | F23: =IFERROR(ROUND(State_lookup!H22/SUM(State_lookup!H2:H49)*National_totals!$G$4, 0), 0) -> 0 | G23: =IFERROR(ROUND(State_lookup!H22/SUM(State_lookup!H2:H49)*National_totals!$H$4, 0), 0) -> 0 | H23: =IFERROR(ROUND(State_lookup!H22/SUM(State_lookup!H2:H49)*National_totals!$I$4, 0), 0) -> 0
A24: =State_lookup!B23 -> Mississippi | B24: =IFERROR(ROUND(State_lookup!H23/SUM(State_lookup!H2:H49)*National_totals!$C$4, 0), 0) -> 0 | C24: =IFERROR(ROUND(State_lookup!H23/SUM(State_lookup!H2:H49)*National_totals!$D$4, 0), 0) -> 0 | D24: =IFERROR(ROUND(State_lookup!H23/SUM(State_lookup!H2:H49)*National_totals!$E$4, 0), 0) -> 0 | E24: =IFERROR(ROUND(MAX(State_lookup!H23/SUM(State_lookup!H2:H49)*National_totals!$F$4, Keys!$C$59), 0), 0) -> 24 | F24: =IFERROR(ROUND(State_lookup!H23/SUM(State_lookup!H2:H49)*National_totals!$G$4, 0), 0) -> 0 | G24: =IFERROR(ROUND(State_lookup!H23/SUM(State_lookup!H2:H49)*National_totals!$H$4, 0), 0) -> 0 | H24: =IFERROR(ROUND(State_lookup!H23/SUM(State_lookup!H2:H49)*National_totals!$I$4, 0), 0) -> 0
A25: =State_lookup!B24 -> Missouri | B25: =IFERROR(ROUND(State_lookup!H24/SUM(State_lookup!H2:H49)*National_totals!$C$4, 0), 0) -> 0 | C25: =IFERROR(ROUND(State_lookup!H24/SUM(State_lookup!H2:H49)*National_totals!$D$4, 0), 0) -> 0 | D25: =IFERROR(ROUND(State_lookup!H24/SUM(State_lookup!H2:H49)*National_totals!$E$4, 0), 0) -> 0 | E25: =IFERROR(ROUND(MAX(State_lookup!H24/SUM(State_lookup!H2:H49)*National_totals!$F$4, Keys!$C$59), 0), 0) -> 107 | F25: =IFERROR(ROUND(State_lookup!H24/SUM(State_lookup!H2:H49)*National_totals!$G$4, 0), 0) -> 0 | G25: =IFERROR(ROUND(State_lookup!H24/SUM(State_lookup!H2:H49)*National_totals!$H$4, 0), 0) -> 0 | H25: =IFERROR(ROUND(State_lookup!H24/SUM(State_lookup!H2:H49)*National_totals!$I$4, 0), 0) -> 0
A26: =State_lookup!B25 -> Montana | B26: =IFERROR(ROUND(State_lookup!H25/SUM(State_lookup!H2:H49)*National_totals!$C$4, 0), 0) -> 0 | C26: =IFERROR(ROUND(State_lookup!H25/SUM(State_lookup!H2:H49)*National_totals!$D$4, 0), 0) -> 0 | D26: =IFERROR(ROUND(State_lookup!H25/SUM(State_lookup!H2:H49)*National_totals!$E$4, 0), 0) -> 0 | E26: =IFERROR(ROUND(MAX(State_lookup!H25/SUM(State_lookup!H2:H49)*National_totals!$F$4, Keys!$C$59), 0), 0) -> 24 | F26: =IFERROR(ROUND(State_lookup!H25/SUM(State_lookup!H2:H49)*National_totals!$G$4, 0), 0) -> 0 | G26: =IFERROR(ROUND(State_lookup!H25/SUM(State_lookup!H2:H49)*National_totals!$H$4, 0), 0) -> 0 | H26: =IFERROR(ROUND(State_lookup!H25/SUM(State_lookup!H2:H49)*National_totals!$I$4, 0), 0) -> 0
A27: =State_lookup!B26 -> Nebraska | B27: =IFERROR(ROUND(State_lookup!H26/SUM(State_lookup!H2:H49)*National_totals!$C$4, 0), 0) -> 0 | C27: =IFERROR(ROUND(State_lookup!H26/SUM(State_lookup!H2:H49)*National_totals!$D$4, 0), 0) -> 0 | D27: =IFERROR(ROUND(State_lookup!H26/SUM(State_lookup!H2:H49)*National_totals!$E$4, 0), 0) -> 0 | E27: =IFERROR(ROUND(MAX(State_lookup!H26/SUM(State_lookup!H2:H49)*National_totals!$F$4, Keys!$C$59), 0), 0) -> 24 | F27: =IFERROR(ROUND(State_lookup!H26/SUM(State_lookup!H2:H49)*National_totals!$G$4, 0), 0) -> 0 | G27: =IFERROR(ROUND(State_lookup!H26/SUM(State_lookup!H2:H49)*National_totals!$H$4, 0), 0) -> 0 | H27: =IFERROR(ROUND(State_lookup!H26/SUM(State_lookup!H2:H49)*National_totals!$I$4, 0), 0) -> 0
A28: =State_lookup!B27 -> Nevada | B28: =IFERROR(ROUND(State_lookup!H27/SUM(State_lookup!H2:H49)*National_totals!$C$4, 0), 0) -> 0 | C28: =IFERROR(ROUND(State_lookup!H27/SUM(State_lookup!H2:H49)*National_totals!$D$4, 0), 0) -> 0 | D28: =IFERROR(ROUND(State_lookup!H27/SUM(State_lookup!H2:H49)*National_totals!$E$4, 0), 0) -> 0 | E28: =IFERROR(ROUND(MAX(State_lookup!H27/SUM(State_lookup!H2:H49)*National_totals!$F$4, Keys!$C$59), 0), 0) -> 203 | F28: =IFERROR(ROUND(State_lookup!H27/SUM(State_lookup!H2:H49)*National_totals!$G$4, 0), 0) -> 0 | G28: =IFERROR(ROUND(State_lookup!H27/SUM(State_lookup!H2:H49)*National_totals!$H$4, 0), 0) -> 0 | H28: =IFERROR(ROUND(State_lookup!H27/SUM(State_lookup!H2:H49)*National_totals!$I$4, 0), 0) -> 0
A29: =State_lookup!B28 -> New Hampshire | B29: =IFERROR(ROUND(State_lookup!H28/SUM(State_lookup!H2:H49)*National_totals!$C$4, 0), 0) -> 0 | C29: =IFERROR(ROUND(State_lookup!H28/SUM(State_lookup!H2:H49)*National_totals!$D$4, 0), 0) -> 0 | D29: =IFERROR(ROUND(State_lookup!H28/SUM(State_lookup!H2:H49)*National_totals!$E$4, 0), 0) -> 0 | E29: =IFERROR(ROUND(MAX(State_lookup!H28/SUM(State_lookup!H2:H49)*National_totals!$F$4, Keys!$C$59), 0), 0) -> 24 | F29: =IFERROR(ROUND(State_lookup!H28/SUM(State_lookup!H2:H49)*National_totals!$G$4, 0), 0) -> 0 | G29: =IFERROR(ROUND(State_lookup!H28/SUM(State_lookup!H2:H49)*National_totals!$H$4, 0), 0) -> 0 | H29: =IFERROR(ROUND(State_lookup!H28/SUM(State_lookup!H2:H49)*National_totals!$I$4, 0), 0) -> 0
A30: =State_lookup!B29 -> New Jersey | B30: =IFERROR(ROUND(State_lookup!H29/SUM(State_lookup!H2:H49)*National_totals!$C$4, 0), 0) -> 0 | C30: =IFERROR(ROUND(State_lookup!H29/SUM(State_lookup!H2:H49)*National_totals!$D$4, 0), 0) -> 0 | D30: =IFERROR(ROUND(State_lookup!H29/SUM(State_lookup!H2:H49)*National_totals!$E$4, 0), 0) -> 0 | E30: =IFERROR(ROUND(MAX(State_lookup!H29/SUM(State_lookup!H2:H49)*National_totals!$F$4, Keys!$C$59), 0), 0) -> 181 | F30: =IFERROR(ROUND(State_lookup!H29/SUM(State_lookup!H2:H49)*National_totals!$G$4, 0), 0) -> 0 | G30: =IFERROR(ROUND(State_lookup!H29/SUM(State_lookup!H2:H49)*National_totals!$H$4, 0), 0) -> 0 | H30: =IFERROR(ROUND(State_lookup!H29/SUM(State_lookup!H2:H49)*National_totals!$I$4, 0), 0) -> 0
A31: =State_lookup!B30 -> New Mexico | B31: =IFERROR(ROUND(State_lookup!H30/SUM(State_lookup!H2:H49)*National_totals!$C$4, 0), 0) -> 0 | C31: =IFERROR(ROUND(State_lookup!H30/SUM(State_lookup!H2:H49)*National_totals!$D$4, 0), 0) -> 0 | D31: =IFERROR(ROUND(State_lookup!H30/SUM(State_lookup!H2:H49)*National_totals!$E$4, 0), 0) -> 0 | E31: =IFERROR(ROUND(MAX(State_lookup!H30/SUM(State_lookup!H2:H49)*National_totals!$F$4, Keys!$C$59), 0), 0) -> 24 | F31: =IFERROR(ROUND(State_lookup!H30/SUM(State_lookup!H2:H49)*National_totals!$G$4, 0), 0) -> 0 | G31: =IFERROR(ROUND(State_lookup!H30/SUM(State_lookup!H2:H49)*National_totals!$H$4, 0), 0) -> 0 | H31: =IFERROR(ROUND(State_lookup!H30/SUM(State_lookup!H2:H49)*National_totals!$I$4, 0), 0) -> 0
A32: =State_lookup!B31 -> New York | B32: =IFERROR(ROUND(State_lookup!H31/SUM(State_lookup!H2:H49)*National_totals!$C$4, 0), 0) -> 0 | C32: =IFERROR(ROUND(State_lookup!H31/SUM(State_lookup!H2:H49)*National_totals!$D$4, 0), 0) -> 0 | D32: =IFERROR(ROUND(State_lookup!H31/SUM(State_lookup!H2:H49)*National_totals!$E$4, 0), 0) -> 0 | E32: =IFERROR(ROUND(MAX(State_lookup!H31/SUM(State_lookup!H2:H49)*National_totals!$F$4, Keys!$C$59), 0), 0) -> 415 | F32: =IFERROR(ROUND(State_lookup!H31/SUM(State_lookup!H2:H49)*National_totals!$G$4, 0), 0) -> 0 | G32: =IFERROR(ROUND(State_lookup!H31/SUM(State_lookup!H2:H49)*National_totals!$H$4, 0), 0) -> 0 | H32: =IFERROR(ROUND(State_lookup!H31/SUM(State_lookup!H2:H49)*National_totals!$I$4, 0), 0) -> 0
A33: =State_lookup!B32 -> North Carolina | B33: =IFERROR(ROUND(State_lookup!H32/SUM(State_lookup!H2:H49)*National_totals!$C$4, 0), 0) -> 0 | C33: =IFERROR(ROUND(State_lookup!H32/SUM(State_lookup!H2:H49)*National_totals!$D$4, 0), 0) -> 0 | D33: =IFERROR(ROUND(State_lookup!H32/SUM(State_lookup!H2:H49)*National_totals!$E$4, 0), 0) -> 0 | E33: =IFERROR(ROUND(MAX(State_lookup!H32/SUM(State_lookup!H2:H49)*National_totals!$F$4, Keys!$C$59), 0), 0) -> 257 | F33: =IFERROR(ROUND(State_lookup!H32/SUM(State_lookup!H2:H49)*National_totals!$G$4, 0), 0) -> 0 | G33: =IFERROR(ROUND(State_lookup!H32/SUM(State_lookup!H2:H49)*National_totals!$H$4, 0), 0) -> 0 | H33: =IFERROR(ROUND(State_lookup!H32/SUM(State_lookup!H2:H49)*National_totals!$I$4, 0), 0) -> 0
A34: =State_lookup!B33 -> North Dakota | B34: =IFERROR(ROUND(State_lookup!H33/SUM(State_lookup!H2:H49)*National_totals!$C$4, 0), 0) -> 0 | C34: =IFERROR(ROUND(State_lookup!H33/SUM(State_lookup!H2:H49)*National_totals!$D$4, 0), 0) -> 0 | D34: =IFERROR(ROUND(State_lookup!H33/SUM(State_lookup!H2:H49)*National_totals!$E$4, 0), 0) -> 0 | E34: =IFERROR(ROUND(MAX(State_lookup!H33/SUM(State_lookup!H2:H49)*National_totals!$F$4, Keys!$C$59), 0), 0) -> 24 | F34: =IFERROR(ROUND(State_lookup!H33/SUM(State_lookup!H2:H49)*National_totals!$G$4, 0), 0) -> 0 | G34: =IFERROR(ROUND(State_lookup!H33/SUM(State_lookup!H2:H49)*National_totals!$H$4, 0), 0) -> 0 | H34: =IFERROR(ROUND(State_lookup!H33/SUM(State_lookup!H2:H49)*National_totals!$I$4, 0), 0) -> 0
A35: =State_lookup!B34 -> Ohio | B35: =IFERROR(ROUND(State_lookup!H34/SUM(State_lookup!H2:H49)*National_totals!$C$4, 0), 0) -> 0 | C35: =IFERROR(ROUND(State_lookup!H34/SUM(State_lookup!H2:H49)*National_totals!$D$4, 0), 0) -> 0 | D35: =IFERROR(ROUND(State_lookup!H34/SUM(State_lookup!H2:H49)*National_totals!$E$4, 0), 0) -> 0 | E35: =IFERROR(ROUND(MAX(State_lookup!H34/SUM(State_lookup!H2:H49)*National_totals!$F$4, Keys!$C$59), 0), 0) -> 80 | F35: =IFERROR(ROUND(State_lookup!H34/SUM(State_lookup!H2:H49)*National_totals!$G$4, 0), 0) -> 0 | G35: =IFERROR(ROUND(State_lookup!H34/SUM(State_lookup!H2:H49)*National_totals!$H$4, 0), 0) -> 0 | H35: =IFERROR(ROUND(State_lookup!H34/SUM(State_lookup!H2:H49)*National_totals!$I$4, 0), 0) -> 0
A36: =State_lookup!B35 -> Oklahoma | B36: =IFERROR(ROUND(State_lookup!H35/SUM(State_lookup!H2:H49)*National_totals!$C$4, 0), 0) -> 0 | C36: =IFERROR(ROUND(State_lookup!H35/SUM(State_lookup!H2:H49)*National_totals!$D$4, 0), 0) -> 0 | D36: =IFERROR(ROUND(State_lookup!H35/SUM(State_lookup!H2:H49)*National_totals!$E$4, 0), 0) -> 0 | E36: =IFERROR(ROUND(MAX(State_lookup!H35/SUM(State_lookup!H2:H49)*National_totals!$F$4, Keys!$C$59), 0), 0) -> 28 | F36: =IFERROR(ROUND(State_lookup!H35/SUM(State_lookup!H2:H49)*National_totals!$G$4, 0), 0) -> 0 | G36: =IFERROR(ROUND(State_lookup!H35/SUM(State_lookup!H2:H49)*National_totals!$H$4, 0), 0) -> 0 | H36: =IFERROR(ROUND(State_lookup!H35/SUM(State_lookup!H2:H49)*National_totals!$I$4, 0), 0) -> 0
A37: =State_lookup!B36 -> Oregon | B37: =IFERROR(ROUND(State_lookup!H36/SUM(State_lookup!H2:H49)*National_totals!$C$4, 0), 0) -> 0 | C37: =IFERROR(ROUND(State_lookup!H36/SUM(State_lookup!H2:H49)*National_totals!$D$4, 0), 0) -> 0 | D37: =IFERROR(ROUND(State_lookup!H36/SUM(State_lookup!H2:H49)*National_totals!$E$4, 0), 0) -> 0 | E37: =IFERROR(ROUND(MAX(State_lookup!H36/SUM(State_lookup!H2:H49)*National_totals!$F$4, Keys!$C$59), 0), 0) -> 85 | F37: =IFERROR(ROUND(State_lookup!H36/SUM(State_lookup!H2:H49)*National_totals!$G$4, 0), 0) -> 0 | G37: =IFERROR(ROUND(State_lookup!H36/SUM(State_lookup!H2:H49)*National_totals!$H$4, 0), 0) -> 0 | H37: =IFERROR(ROUND(State_lookup!H36/SUM(State_lookup!H2:H49)*National_totals!$I$4, 0), 0) -> 0
A38: =State_lookup!B37 -> Pennsylvania | B38: =IFERROR(ROUND(State_lookup!H37/SUM(State_lookup!H2:H49)*National_totals!$C$4, 0), 0) -> 0 | C38: =IFERROR(ROUND(State_lookup!H37/SUM(State_lookup!H2:H49)*National_totals!$D$4, 0), 0) -> 0 | D38: =IFERROR(ROUND(State_lookup!H37/SUM(State_lookup!H2:H49)*National_totals!$E$4, 0), 0) -> 0 | E38: =IFERROR(ROUND(MAX(State_lookup!H37/SUM(State_lookup!H2:H49)*National_totals!$F$4, Keys!$C$59), 0), 0) -> 170 | F38: =IFERROR(ROUND(State_lookup!H37/SUM(State_lookup!H2:H49)*National_totals!$G$4, 0), 0) -> 0 | G38: =IFERROR(ROUND(State_lookup!H37/SUM(State_lookup!H2:H49)*National_totals!$H$4, 0), 0) -> 0 | H38: =IFERROR(ROUND(State_lookup!H37/SUM(State_lookup!H2:H49)*National_totals!$I$4, 0), 0) -> 0
A39: =State_lookup!B38 -> Rhode Island | B39: =IFERROR(ROUND(State_lookup!H38/SUM(State_lookup!H2:H49)*National_totals!$C$4, 0), 0) -> 0 | C39: =IFERROR(ROUND(State_lookup!H38/SUM(State_lookup!H2:H49)*National_totals!$D$4, 0), 0) -> 0 | D39: =IFERROR(ROUND(State_lookup!H38/SUM(State_lookup!H2:H49)*National_totals!$E$4, 0), 0) -> 0 | E39: =IFERROR(ROUND(MAX(State_lookup!H38/SUM(State_lookup!H2:H49)*National_totals!$F$4, Keys!$C$59), 0), 0) -> 24 | F39: =IFERROR(ROUND(State_lookup!H38/SUM(State_lookup!H2:H49)*National_totals!$G$4, 0), 0) -> 0 | G39: =IFERROR(ROUND(State_lookup!H38/SUM(State_lookup!H2:H49)*National_totals!$H$4, 0), 0) -> 0 | H39: =IFERROR(ROUND(State_lookup!H38/SUM(State_lookup!H2:H49)*National_totals!$I$4, 0), 0) -> 0
A40: =State_lookup!B39 -> South Carolina | B40: =IFERROR(ROUND(State_lookup!H39/SUM(State_lookup!H2:H49)*National_totals!$C$4, 0), 0) -> 0 | C40: =IFERROR(ROUND(State_lookup!H39/SUM(State_lookup!H2:H49)*National_totals!$D$4, 0), 0) -> 0 | D40: =IFERROR(ROUND(State_lookup!H39/SUM(State_lookup!H2:H49)*National_totals!$E$4, 0), 0) -> 0 | E40: =IFERROR(ROUND(MAX(State_lookup!H39/SUM(State_lookup!H2:H49)*National_totals!$F$4, Keys!$C$59), 0), 0) -> 43 | F40: =IFERROR(ROUND(State_lookup!H39/SUM(State_lookup!H2:H49)*National_totals!$G$4, 0), 0) -> 0 | G40: =IFERROR(ROUND(State_lookup!H39/SUM(State_lookup!H2:H49)*National_totals!$H$4, 0), 0) -> 0 | H40: =IFERROR(ROUND(State_lookup!H39/SUM(State_lookup!H2:H49)*National_totals!$I$4, 0), 0) -> 0
...

Sheet SSYVbT-passenger-rail
A1: passenger rail — vehicles 2024 (v2 direct-state)
A2: State | B2: battery electric vehicle | C2: natural gas vehicle | D2: gasoline vehicle | E2: diesel vehicle | F2: plugin hybrid vehicle | G2: LPG vehicle | H2: hydrogen vehicle
A3: =State_lookup!B2 -> Alabama | B3: =IFERROR(ROUND(State_lookup!K2/SUM(State_lookup!K2:K49)*National_totals!$C$5, 0), 0) -> 0 | C3: =IFERROR(ROUND(State_lookup!J2/SUM(State_lookup!J2:J49)*National_totals!$D$5, 0), 0) -> 0 | D3: =IFERROR(ROUND(State_lookup!J2/SUM(State_lookup!J2:J49)*National_totals!$E$5, 0), 0) -> 0 | E3: =IFERROR(ROUND(State_lookup!J2/SUM(State_lookup!J2:J49)*National_totals!$F$5, 0), 0) -> 0 | F3: =IFERROR(ROUND(State_lookup!J2/SUM(State_lookup!J2:J49)*National_totals!$G$5, 0), 0) -> 0 | G3: =IFERROR(ROUND(State_lookup!J2/SUM(State_lookup!J2:J49)*National_totals!$H$5, 0), 0) -> 0 | H3: =IFERROR(ROUND(State_lookup!J2/SUM(State_lookup!J2:J49)*National_totals!$I$5, 0), 0) -> 0
A4: =State_lookup!B3 -> Arizona | B4: =IFERROR(ROUND(State_lookup!K3/SUM(State_lookup!K2:K49)*National_totals!$C$5, 0), 0) -> 21 | C4: =IFERROR(ROUND(State_lookup!J3/SUM(State_lookup!J2:J49)*National_totals!$D$5, 0), 0) -> 0 | D4: =IFERROR(ROUND(State_lookup!J3/SUM(State_lookup!J2:J49)*National_totals!$E$5, 0), 0) -> 0 | E4: =IFERROR(ROUND(State_lookup!J3/SUM(State_lookup!J2:J49)*National_totals!$F$5, 0), 0) -> 0 | F4: =IFERROR(ROUND(State_lookup!J3/SUM(State_lookup!J2:J49)*National_totals!$G$5, 0), 0) -> 0 | G4: =IFERROR(ROUND(State_lookup!J3/SUM(State_lookup!J2:J49)*National_totals!$H$5, 0), 0) -> 0 | H4: =IFERROR(ROUND(State_lookup!J3/SUM(State_lookup!J2:J49)*National_totals!$I$5, 0), 0) -> 0
A5: =State_lookup!B4 -> Arkansas | B5: =IFERROR(ROUND(State_lookup!K4/SUM(State_lookup!K2:K49)*National_totals!$C$5, 0), 0) -> 3 | C5: =IFERROR(ROUND(State_lookup!J4/SUM(State_lookup!J2:J49)*National_totals!$D$5, 0), 0) -> 0 | D5: =IFERROR(ROUND(State_lookup!J4/SUM(State_lookup!J2:J49)*National_totals!$E$5, 0), 0) -> 0 | E5: =IFERROR(ROUND(State_lookup!J4/SUM(State_lookup!J2:J49)*National_totals!$F$5, 0), 0) -> 0 | F5: =IFERROR(ROUND(State_lookup!J4/SUM(State_lookup!J2:J49)*National_totals!$G$5, 0), 0) -> 0 | G5: =IFERROR(ROUND(State_lookup!J4/SUM(State_lookup!J2:J49)*National_totals!$H$5, 0), 0) -> 0 | H5: =IFERROR(ROUND(State_lookup!J4/SUM(State_lookup!J2:J49)*National_totals!$I$5, 0), 0) -> 0
