Workbook

Sheet About
A1: BDCSoCbIC - BAU Domestic Content Share by ISIC Code
A3: State: Maine (ME) Base year: 2019 Pipeline: EPS IO Pipeline — stateior-based
A4: Deflator: 2019 USD -> 2012 USD = 1.12266 (BEA chained GDP price index; 2012 = 100.000, 2019 = 112.266)
A6: =========================================================
A7: Methodology
A8: =========================================================
A9: For each 42-ISIC commodity i, domestic content share =
A10: DCS(i) = SoI-produced-consumed-in-SoI(i)
A11: / total-consumed-in-SoI(i)
A13: where:
A14: numerator = rowSums(DomesticUse[i/US-<ST>, j/US-<ST>])
A15: denominator = rowSums(Use[i/US-<ST>, j/US-<ST>]) +
... A133: - BDCSoCbIC / BESoP - final fraction rows (match the CSVs)

Sheet Keys
A1: category | B1: key | C1: value | D1: description
A2: deflator | B2: deflator_nominal_to_2012 | C2: 1.12266 | D2: Divide nominal 2019 USD by this to get 2012 USD. BEA chained GDP price index; 2012 = 100.000, 2019 = 112.266
A3: year | B3: base_year | C3: 2019 | D3: stateior base year; nominal-USD vintage of the source tabs
A4: numeric | B4: epsilon_div_floor | C4: 1e-09 | D4: Denominator floor for ratio outputs (DCS, ESoP): x/MAX(den, epsilon) avoids div-by-zero; mirrors pmax(den, 1e-9) in the R pipeline
A5: numeric | B5: fogp_denom_floor_usd | C5: 1 | D5: FoGP-entity denominator floor: total purchases per category floored at $1 (mirrors pmax(total, 1)); near-zero totals give near-zero fractions

Sheet 1_DCS_numerator_by_BEA
A1: BEA_Summary_code | B1: SoI_supply_to_SoI_USD
A2: 111CA | B2: 4.0659825e+08
A3: 113FF | B3: 2.7327792e+08
A4: 211 | B4: 809715.6
A5: 212 | B5: 58868077
A6: 213 | B6: 615999.62
A7: 22 | B7: 3.0306578e+08
A8: 23 | B8: 9.7551409e+08
A9: 321 | B9: 2.6789896e+08
A10: 327 | B10: 1.9051868e+08
A11: 331 | B11: 43342465
A12: 332 | B12: 2.8138773e+08
A13: 333 | B13: 67844030
... A74: Other | B74: 0

Sheet 2_DCS_denominator_by_BEA
A1: BEA_Summary_code | B1: total_supply_in_SoI_USD
A2: 111CA | B2: 1.0711142e+09
A3: 113FF | B3: 3.4530093e+08
A4: 211 | B4: 2.8169574e+08
A5: 212 | B5: 1.6958358e+08
A6: 213 | B6: 949358.75
A7: 22 | B7: 1.279961e+09
A8: 23 | B8: 9.7551409e+08
A9: 321 | B9: 4.8165079e+08
A10: 327 | B10: 3.5448625e+08
A11: 331 | B11: 5.3346639e+08
A12: 332 | B12: 9.9683992e+08
A13: 333 | B13: 4.1211962e+08
... A74: Other | B74: 2.6833235e+08

Sheet 3_ESoP_RoUS_exports_by_BEA
A1: BEA_Summary_code | B1: exports_to_RoUS_USD
A2: 111CA | B2: 3.2762652e+08
A3: 113FF | B3: 43471456
A4: 211 | B4: 3.6878278e-05
A5: 212 | B5: 32317.909
A6: 213 | B6: 3.0012376
A7: 22 | B7: 1.3659495e+09
A8: 23 | B8: 0
A9: 321 | B9: 6.0012486e+08
A10: 327 | B10: 71249043
A11: 331 | B11: 52445255
A12: 332 | B12: 8.5493282e+08
A13: 333 | B13: 3.8900202e+08
... A74: Other | B74: 0

Sheet 4_ESoP_intl_exports_by_BEA
A1: BEA_Summary_code | B1: exports_intl_USD
A2: 111CA | B2: 97122377
A3: 113FF | B3: 6.2552299e+08
A4: 211 | B4: 329477.68
A5: 212 | B5: 14166548
A6: 213 | B6: 56673.299
A7: 22 | B7: 12635456
A8: 23 | B8: 272315.82
A9: 321 | B9: 45307964
A10: 327 | B10: 1698594.3
A11: 331 | B11: 7593458.3
A12: 332 | B12: 25552622
A13: 333 | B13: 1.1443237e+08
... A74: Other | B74: 9.5462556e+08

Sheet 5_Exp_total_by_BEA
A1: BEA_Summary_code | B1: exports_total_USD (= RoUS + intl)
A2: ='3_ESoP_RoUS_exports_by_BEA'!A2 | B2: ='3_ESoP_RoUS_exports_by_BEA'!B2+'4_ESoP_intl_exports_by_BEA'!B2
A3: ='3_ESoP_RoUS_exports_by_BEA'!A3 | B3: ='3_ESoP_RoUS_exports_by_BEA'!B3+'4_ESoP_intl_exports_by_BEA'!B3
A4: ='3_ESoP_RoUS_exports_by_BEA'!A4 | B4: ='3_ESoP_RoUS_exports_by_BEA'!B4+'4_ESoP_intl_exports_by_BEA'!B4
A5: ='3_ESoP_RoUS_exports_by_BEA'!A5 | B5: ='3_ESoP_RoUS_exports_by_BEA'!B5+'4_ESoP_intl_exports_by_BEA'!B5
A6: ='3_ESoP_RoUS_exports_by_BEA'!A6 | B6: ='3_ESoP_RoUS_exports_by_BEA'!B6+'4_ESoP_intl_exports_by_BEA'!B6
A7: ='3_ESoP_RoUS_exports_by_BEA'!A7 | B7: ='3_ESoP_RoUS_exports_by_BEA'!B7+'4_ESoP_intl_exports_by_BEA'!B7
A8: ='3_ESoP_RoUS_exports_by_BEA'!A8 | B8: ='3_ESoP_RoUS_exports_by_BEA'!B8+'4_ESoP_intl_exports_by_BEA'!B8
A9: ='3_ESoP_RoUS_exports_by_BEA'!A9 | B9: ='3_ESoP_RoUS_exports_by_BEA'!B9+'4_ESoP_intl_exports_by_BEA'!B9
A10: ='3_ESoP_RoUS_exports_by_BEA'!A10 | B10: ='3_ESoP_RoUS_exports_by_BEA'!B10+'4_ESoP_intl_exports_by_BEA'!B10
A11: ='3_ESoP_RoUS_exports_by_BEA'!A11 | B11: ='3_ESoP_RoUS_exports_by_BEA'!B11+'4_ESoP_intl_exports_by_BEA'!B11
A12: ='3_ESoP_RoUS_exports_by_BEA'!A12 | B12: ='3_ESoP_RoUS_exports_by_BEA'!B12+'4_ESoP_intl_exports_by_BEA'!B12
A13: ='3_ESoP_RoUS_exports_by_BEA'!A13 | B13: ='3_ESoP_RoUS_exports_by_BEA'!B13+'4_ESoP_intl_exports_by_BEA'!B13
... A74: ='3_ESoP_RoUS_exports_by_BEA'!A74 | B74: ='3_ESoP_RoUS_exports_by_BEA'!B74+'4_ESoP_intl_exports_by_BEA'!B74

Sheet Src_Stateior_SoI_DomUse
A1: State-of-Interest Domestic Use matrix at BEA Summary resolution, from
A2: EPA stateior. Rows = commodities, columns = industries + final demand
A3: categories (F01* PCE, F02* investment, F06* fed nondefense, F07* fed
A4: defense, F10* state and local, F040 intl exports, F050 intl imports).
A5: Values in nominal 2019 USD. This is the raw input used to compute
A6: DCS, ESoP, government/household expenditures, and Leontief coefficients.
A9: commodity | B9: 111CA | C9: 113FF | D9: 211 | E9: 212 | F9: 213 | G9: 22 | H9: 23 | I9: 321 | J9: 327 | K9: 331 | L9: 332 | M9: 333 | N9: 334 | O9: 335 | P9: 3361MV | Q9: 3364OT | R9: 337 | S9: 339 | T9: 311FT | U9: 313TT | V9: 315AL | W9: 322 | X9: 323 | Y9: 324 | Z9: 325 | AA9: 326 | AB9: 42 | AC9: 441 | AD9: 445 | AE9: 452 | AF9: 4A0 | AG9: 481 | AH9: 482 | AI9: 483 | AJ9: 484 | AK9: 485 | AL9: 486 | AM9: 487OS | AN9: 493 | AO9: 511 | AP9: 512 | AQ9: 513 | AR9: 514 | AS9: 521CI | AT9: 523 | AU9: 524 | AV9: 525 | AW9: HS | AX9: ORE | AY9: 532RL | AZ9: 5411 | BA9: 5415 | BB9: 5412OP | BC9: 55 | BD9: 561 | BE9: 562 | BF9: 61 | BG9: 621 | BH9: 622 | BI9: 623 | BJ9: 624 | BK9: 711AS | BL9: 713 | BM9: 721 | BN9: 722 | BO9: 81 | BP9: GFGD | BQ9: GFGN | BR9: GFE | BS9: GSLG | BT9: GSLE | BU9: F010 | BV9: F02S | BW9: F02E | BX9: F02N | BY9: F02R | BZ9: F030 | CA9: F040 | CB9: F050 | CC9: F06C | CD9: F06S | CE9: F06E | CF9: F06N | CG9: F07C | CH9: F07S | CI9: F07E | CJ9: F07N | CK9: F10C | CL9: F10S | CM9: F10E | CN9: F10N
A10: 111CA | B10: 92421650 | C10: 920762.93 | D10: 0 | E10: 6150.7539 | F10: 71.665661 | G10: 0 | H10: 1444764.3 | I10: 0 | J10: 0 | K10: 0 | L10: 0 | M10: 0 | N10: 0 | O10: 0 | P10: 0 | Q10: 0 | R10: 0 | S10: 204225.46 | T10: 2.8207071e+08 | U10: 4119187.1 | V10: 0 | W10: 0 | X10: 0 | Y10: 0 | Z10: 11064018 | AA10: 0 | AB10: 833330.25 | AC10: 1084904.6 | AD10: 2220595.9 | AE10: 240913.02 | AF10: 523395.54 | AG10: 0 | AH10: 0 | AI10: 0 | AJ10: 0 | AK10: 0 | AL10: 0 | AM10: 21312.979 | AN10: 0 | AO10: 0 | AP10: 0 | AQ10: 0 | AR10: 0 | AS10: 1096.5782 | AT10: 0 | AU10: 0 | AV10: 0 | AW10: 0 | AX10: 4773.3049 | AY10: 0 | AZ10: 971.23553 | BA10: 0 | BB10: 864352.05 | BC10: 30789.112 | BD10: 1872780.6 | BE10: 0 | BF10: 159540.37 | BG10: 0 | BH10: 0 | BI10: 0 | BJ10: 0 | BK10: 0 | BL10: 553430.66 | BM10: 77455.925 | BN10: 2492652 | BO10: 14789.878 | BP10: 5657.5783 | BQ10: -898094.89 | BR10: 0 | BS10: 4242066.7 | BT10: 0 | BU10: 1.1426874e+08 | BV10: 0 | BW10: 0 | BX10: 0 | BY10: 0 | BZ10: -32760634 | CA10: 97122377 | CB10: 0 | CC10: 0 | CD10: 0 | CE10: 0 | CF10: 0 | CG10: 0 | CH10: 0 | CI10: 0 | CJ10: 0 | CK10: 0 | CL10: 0 | CM10: 0 | CN10: 0
A11: 113FF | B11: 66085127 | C11: 61684198 | D11: 0 | E11: 58345.013 | F11: 0 | G11: 0 | H11: 0 | I11: 89809825 | J11: 0 | K11: 0 | L11: 0 | M11: 0 | N11: 0 | O11: 0 | P11: 0 | Q11: 0 | R11: 43112.625 | S11: 99951.574 | T11: 3013499.5 | U11: 0 | V11: 490707.1 | W11: 33310850 | X11: 11798.292 | Y11: 0 | Z11: 142151.03 | AA11: 1126758.1 | AB11: 0 | AC11: 0 | AD11: 396812.32 | AE11: 0 | AF11: 0 | AG11: 0 | AH11: 0 | AI11: 0 | AJ11: 0 | AK11: 0 | AL11: 0 | AM11: 0 | AN11: 0 | AO11: 0 | AP11: 0 | AQ11: 0 | AR11: 0 | AS11: 0 | AT11: 0 | AU11: 0 | AV11: 0 | AW11: 0 | AX11: 0 | AY11: 0 | AZ11: 0 | BA11: 0 | BB11: 692255.17 | BC11: 75592.084 | BD11: 0 | BE11: 0 | BF11: 28760.935 | BG11: 0 | BH11: 0 | BI11: 0 | BJ11: 0 | BK11: 0 | BL11: 82787.044 | BM11: 203525.2 | BN11: 2008829.2 | BO11: 22056.962 | BP11: 0 | BQ11: 198144.77 | BR11: 4033.5026 | BS11: 13688802 | BT11: 0 | BU11: 18065432 | BV11: 0 | BW11: 0 | BX11: 0 | BY11: 0 | BZ11: 16561510 | CA11: 6.2552299e+08 | CB11: 0 | CC11: 0 | CD11: 0 | CE11: 0 | CF11: 0 | CG11: 0 | CH11: 0 | CI11: 0 | CJ11: 0 | CK11: 0 | CL11: 0 | CM11: 0 | CN11: 0
A12: 211 | B12: 0 | C12: 0 | D12: 0 | E12: 0 | F12: 0.23871401 | G12: 175963.21 | H12: 0 | I12: 115.15404 | J12: 9.5635005 | K12: 5.2262033 | L12: 0 | M12: 0 | N12: 0 | O12: 0 | P12: 2.6231916 | Q12: 0 | R12: 0 | S12: 0 | T12: 15.881123 | U12: 0 | V12: 0 | W12: 0 | X12: 11.179411 | Y12: 470900.14 | Z12: 32629.249 | AA12: 0 | AB12: 25.953931 | AC12: 44.614223 | AD12: 0 | AE12: 20.111949 | AF12: 53.643048 | AG12: 0 | AH12: 0 | AI12: 0 | AJ12: 0 | AK12: 0 | AL12: 30.660272 | AM12: 0 | AN12: 629.68662 | AO12: 206.75403 | AP12: 0 | AQ12: 6.4821974 | AR12: 27.757598 | AS12: 0 | AT12: 0 | AU12: 0 | AV12: 0 | AW12: 0 | AX12: 201.39483 | AY12: 0 | AZ12: 0 | BA12: 9.8420318 | BB12: 33.017255 | BC12: 32.557677 | BD12: 0 | BE12: 18.300036 | BF12: 2491.6366 | BG12: 17.015635 | BH12: 0 | BI12: 30.231059 | BJ12: 0 | BK12: 0 | BL12: 317.51319 | BM12: 26.06071 | BN12: 19.034557 | BO12: 44.78563 | BP12: 0 | BQ12: 0 | BR12: 16529.824 | BS12: 0 | BT12: 109246.25 | BU12: 0 | BV12: 0 | BW12: 0 | BX12: 0 | BY12: 0 | BZ12: 17895.203 | CA12: 329477.68 | CB12: 0 | CC12: 0 | CD12: 0 | CE12: 0 | CF12: 0 | CG12: 0 | CH12: 0 | CI12: 0 | CJ12: 0 | CK12: 0 | CL12: 0 | CM12: 0 | CN12: 0
A13: 212 | B13: 1213487.1 | C13: 0 | D13: 0 | E13: 1628961.8 | F13: 474.41877 | G13: 5764952.4 | H13: 14128462 | I13: 25428.494 | J13: 6725113.1 | K13: 915601.02 | L13: 565916.3 | M13: 51587.724 | N13: 1976.6736 | O13: 8426.6774 | P13: 8254.4157 | Q13: 164604.85 | R13: 12215.684 | S13: 46000.084 | T13: 1288783.6 | U13: 86020.707 | V13: 0 | W13: 6220327.3 | X13: 0 | Y13: 790909.77 | Z13: 2962220.6 | AA13: 137844.12 | AB13: 12895.171 | AC13: 0 | AD13: 0 | AE13: 0 | AF13: 1480.6926 | AG13: 0 | AH13: 65945.866 | AI13: 0 | AJ13: 7249.1824 | AK13: 825.01913 | AL13: 0 | AM13: 851.99017 | AN13: 2317.4729 | AO13: 7462.9583 | AP13: 4117.827 | AQ13: 140099.14 | AR13: 177244.01 | AS13: 0 | AT13: 0 | AU13: 0 | AV13: 0 | AW13: 7561.4672 | AX13: 0 | AY13: 0 | AZ13: 0 | BA13: 0 | BB13: 942351.61 | BC13: 40440.581 | BD13: 880052.33 | BE13: 69707.982 | BF13: 612535.2 | BG13: 0 | BH13: 42711.52 | BI13: 70094.529 | BJ13: 265690.2 | BK13: 209608.04 | BL13: 941895.82 | BM13: 284860.94 | BN13: 1033997.1 | BO13: 1354879.6 | BP13: 0 | BQ13: 3598337.2 | BR13: 0 | BS13: 1709803.3 | BT13: 3635490.7 | BU13: 357263.57 | BV13: 0 | BW13: 1287.259 | BX13: 0 | BY13: 0 | BZ13: 482474.02 | CA13: 14166548 | CB13: 0 | CC13: 0 | CD13: 0 | CE13: 0 | CF13: 0 | CG13: 0 | CH13: 0 | CI13: 0 | CJ13: 0 | CK13: 0 | CL13: 0 | CM13: 0 | CN13: 0
A14: 213 | B14: 0 | C14: 0 | D14: 0 | E14: 540876.36 | F14: 21621.376 | G14: 0 | H14: 0 | I14: 0 | J14: 0 | K14: 0 | L14: 0 | M14: 0 | N14: 0 | O14: 0 | P14: 0 | Q14: 0 | R14: 0 | S14: 0 | T14: 0 | U14: 0 | V14: 0 | W14: 0 | X14: 0 | Y14: 0 | Z14: 0 | AA14: 0 | AB14: 0 | AC14: 0 | AD14: 0 | AE14: 0 | AF14: 0 | AG14: 0 | AH14: 0 | AI14: 0 | AJ14: 0 | AK14: 0 | AL14: 0 | AM14: 0 | AN14: 0 | AO14: 0 | AP14: 0 | AQ14: 0 | AR14: 0 | AS14: 0 | AT14: 0 | AU14: 0 | AV14: 0 | AW14: 0 | AX14: 0 | AY14: 0 | AZ14: 0 | BA14: 0 | BB14: 46401.829 | BC14: 7100.0605 | BD14: 0 | BE14: 0 | BF14: 0 | BG14: 0 | BH14: 0 | BI14: 0 | BJ14: 0 | BK14: 0 | BL14: 0 | BM14: 0 | BN14: 0 | BO14: 0 | BP14: 0 | BQ14: 0 | BR14: 0 | BS14: 0 | BT14: 0 | BU14: 0 | BV14: 2654195.7 | BW14: 44678.57 | BX14: 0 | BY14: 0 | BZ14: -136.28849 | CA14: 56673.299 | CB14: 0 | CC14: 0 | CD14: 0 | CE14: 0 | CF14: 0 | CG14: 0 | CH14: 0 | CI14: 0 | CJ14: 0 | CK14: 0 | CL14: 0 | CM14: 0 | CN14: 0
A15: 22 | B15: 6532678.6 | C15: 139950.84 | D15: 0 | E15: 752185.11 | F15: 1681.895 | G15: 22793672 | H15: 5770026.4 | I15: 3604587.4 | J15: 2059145.2 | K15: 477037.15 | L15: 4138111.4 | M15: 1073575.3 | N15: 682356.19 | O15: 117008.46 | P15: 454604.16 | Q15: 4866365.3 | R15: 380661.18 | S15: 476425.86 | T15: 7926854 | U15: 1436792.1 | V15: 73852.476 | W15: 18580093 | X15: 748278.92 | Y15: 1164937.7 | Z15: 7535319.6 | AA15: 3913721.8 | AB15: 10849601 | AC15: 5432854.4 | AD15: 16167439 | AE15: 8789736.8 | AF15: 16553649 | AG15: 245282.13 | AH15: 27180.529 | AI15: 38372.931 | AJ15: 3596407 | AK15: 254067.56 | AL15: 252831.13 | AM15: 838512.88 | AN15: 1957085.3 | AO15: 249197.15 | AP15: 77131.818 | AQ15: 2186086.7 | AR15: 649630.62 | AS15: 2235504.5 | AT15: 351038.73 | AU15: 597593.6 | AV15: 1246381.6 | AW15: 201650.27 | AX15: 20972254 | AY15: 659938.32 | AZ15: 395201.93 | BA15: 465739.91 | BB15: 3609784.4 | BC15: 4833451.6 | BD15: 2409193.7 | BE15: 1481797.5 | BF15: 6023340 | BG15: 3984873.5 | BH15: 13127550 | BI15: 6281834.4 | BJ15: 1805633.4 | BK15: 633692.38 | BL15: 3533378.8 | BM15: 8865570.8 | BN15: 20899266 | BO15: 6197060.7 | BP15: 1275210.4 | BQ15: 1645308.3 | BR15: 3014321.3 | BS15: 20484513 | BT15: 1969712.7 | BU15: 2.6861464e+08 | BV15: 0 | BW15: 0 | BX15: 0 | BY15: 0 | BZ15: 0 | CA15: 12635456 | CB15: 0 | CC15: 0 | CD15: 0 | CE15: 0 | CF15: 0 | CG15: 0 | CH15: 0 | CI15: 0 | CJ15: 0 | CK15: 0 | CL15: 0 | CM15: 0 | CN15: 0
A16: 23 | B16: 4379271 | C16: 214192.62 | D16: 0 | E16: 2518119.8 | F16: 24335.627 | G16: 17795763 | H16: 730183.57 | I16: 2675754.9 | J16: 1881466.6 | K16: 406334.33 | L16: 4878604.9 | M16: 1592331.5 | N16: 966698.84 | O16: 102523.64 | P16: 482982.29 | Q16: 2939289.8 | R16: 339010.66 | S16: 681162.34 | T16: 7239795.2 | U16: 747121.97 | V16: 64310.219 | W16: 14407772 | X16: 794148.68 | Y16: 6547371.2 | Z16: 4650424.4 | AA16: 2613576.5 | AB16: 11122400 | AC16: 6777846.6 | AD16: 6970338 | AE16: 8937081.6 | AF16: 14953641 | AG16: 227159.26 | AH16: 3775144 | AI16: 42889.361 | AJ16: 1720957.4 | AK16: 1256735.9 | AL16: 649669.74 | AM16: 2873419.8 | AN16: 2802453.3 | AO16: 165419.36 | AP16: 50208.369 | AQ16: 3419844.5 | AR16: 675697.66 | AS16: 16365820 | AT16: 1928214.9 | AU16: 3058479.1 | AV16: 234529.91 | AW16: 3.5461019e+08 | AX16: 1.0118648e+08 | AY16: 1783177.6 | AZ16: 465353.05 | BA16: 176419.93 | BB16: 5862375.9 | BC16: 3072913.2 | BD16: 2833334.3 | BE16: 595315.44 | BF16: 8675850.5 | BG16: 2850505.5 | BH16: 8129534.5 | BI16: 4482352.7 | BJ16: 3378220.5 | BK16: 573992.41 | BL16: 2533676.6 | BM16: 17272728 | BN16: 10164311 | BO16: 12821503 | BP16: 12641294 | BQ16: 2488321.5 | BR16: 3002536.7 | BS16: 1.2462392e+08 | BT16: 1.2360929e+08 | BU16: 0 | BV16: 1.3796043e+09 | BW16: 0 | BX16: 0 | BY16: 2.5193233e+09 | BZ16: 0 | CA16: 272315.82 | CB16: 0 | CC16: 0 | CD16: 0 | CE16: 0 | CF16: 0 | CG16: 0 | CH16: 1.9174801e+08 | CI16: 0 | CJ16: 0 | CK16: 0 | CL16: 8.0841103e+08 | CM16: 0 | CN16: 0
A17: 321 | B17: 1085844.6 | C17: 427669.42 | D17: 0 | E17: 75678.406 | F17: 1605.6006 | G17: 10233.297 | H17: 58644506 | I17: 1.1036218e+08 | J17: 259176.13 | K17: 114435.35 | L17: 343250.96 | M17: 630821.73 | N17: 341031.33 | O17: 262684.58 | P17: 961259.61 | Q17: 700879.49 | R17: 7108163.6 | S17: 1114595.8 | T17: 767211.92 | U17: 114749.78 | V17: 0 | W17: 29500320 | X17: 0 | Y17: 0 | Z17: 332080.2 | AA17: 3354244.7 | AB17: 11785200 | AC17: 443544.71 | AD17: 2637312 | AE17: 429519.08 | AF17: 2420293.3 | AG17: 0 | AH17: 2245045 | AI17: 0 | AJ17: 378214.36 | AK17: 0 | AL17: 3010.5444 | AM17: 81830.635 | AN17: 218463.11 | AO17: 31232.71 | AP17: 32043.041 | AQ17: 652083.57 | AR17: 442898.57 | AS17: 299475.91 | AT17: 2898.54 | AU17: 0 | AV17: 0 | AW17: 57158.731 | AX17: 11075063 | AY17: 457800.73 | AZ17: 14294.63 | BA17: 34790.15 | BB17: 1240056.4 | BC17: 11988.193 | BD17: 1844950.2 | BE17: 67383.298 | BF17: 83144.405 | BG17: 786933.61 | BH17: 1768374 | BI17: 17810.399 | BJ17: 1960413.4 | BK17: 9205.354 | BL17: 332857.64 | BM17: 2433524.9 | BN17: 1752197.6 | BO17: 628845.23 | BP17: 13457.479 | BQ17: 122902.34 | BR17: 5629.1447 | BS17: 4153261.9 | BT17: 411229.04 | BU17: 4978073.5 | BV17: 1209919.2 | BW17: 0 | BX17: 0 | BY17: 20902458 | BZ17: 3365620.4 | CA17: 45307964 | CB17: 0 | CC17: 0 | CD17: 0 | CE17: 0 | CF17: 0 | CG17: 0 | CH17: 0 | CI17: 253.63788 | CJ17: 0 | CK17: 0 | CL17: 0 | CM17: 0 | CN17: 0
A18: 327 | B18: 35273.88 | C18: 408104.72 | D18: 0 | E18: 213789.9 | F18: 5710.758 | G18: 113691.3 | H18: 1.0798151e+08 | I18: 4088169.9 | J18: 16108944 | K18: 371578.83 | L18: 1826283.6 | M18: 1090939.3 | N18: 242127.41 | O18: 545443.22 | P18: 2148468 | Q18: 670077.09 | R18: 315987.98 | S18: 681021.62 | T18: 6289266.6 | U18: 78695.245 | V18: 0 | W18: 3809486 | X18: 1604.6711 | Y18: 568487.5 | Z18: 1709218.7 | AA18: 2809564.4 | AB18: 126662.83 | AC18: 323393.89 | AD18: 66356.496 | AE18: 840067.63 | AF18: 1008676.4 | AG18: 0 | AH18: 13035.283 | AI18: 0 | AJ18: 154975.8 | AK18: 0 | AL18: 0 | AM18: 14768.248 | AN18: 48204.801 | AO18: 1521.9012 | AP18: 446.11055 | AQ18: 1261679.5 | AR18: 270045.1 | AS18: 15728.769 | AT18: 5649.5792 | AU18: 71465.572 | AV18: 0 | AW18: 301459.02 | AX18: 109545.44 | AY18: 632857.55 | AZ18: 0 | BA18: 255699.83 | BB18: 6129408.2 | BC18: 37386.129 | BD18: 1311599 | BE18: 425533.81 | BF18: 94999.377 | BG18: 4291281.6 | BH18: 4524385.3 | BI18: 377519.79 | BJ18: 1280884.4 | BK18: 14951.889 | BL18: 260046.91 | BM18: 325441.25 | BN18: 3773145.5 | BO18: 3126366.1 | BP18: 44263.35 | BQ18: 583904.17 | BR18: 0 | BS18: 2123590.3 | BT18: 4158290 | BU18: 16536768 | BV18: 0 | BW18: 0 | BX18: 0 | BY18: 0 | BZ18: 2164475.7 | CA18: 1698594.3 | CB18: 0 | CC18: 0 | CD18: 0 | CE18: 0 | CF18: 0 | CG18: 0 | CH18: 0 | CI18: 0 | CJ18: 0 | CK18: 0 | CL18: 0 | CM18: 0 | CN18: 0
A19: 331 | B19: 10614.802 | C19: 0 | D19: 0 | E19: 29205.504 | F19: 334.91333 | G19: 1303.3367 | H19: 835966.51 | I19: 186311.48 | J19: 277394.55 | K19: 1452001.7 | L19: 21874131 | M19: 5561739.4 | N19: 595359.29 | O19: 651854.37 | P19: 2104543.5 | Q19: 3851699.9 | R19: 649236.46 | S19: 778759.17 | T19: 668431.63 | U19: 50745.833 | V19: 0 | W19: 1125168.6 | X19: 2097.1054 | Y19: 454.12127 | Z19: 7552.5912 | AA19: 463679.7 | AB19: 127496.57 | AC19: 2092.2553 | AD19: 0 | AE19: 0 | AF19: 72535.337 | AG19: 0 | AH19: 101721.54 | AI19: 0 | AJ19: 0 | AK19: 0 | AL19: 0 | AM19: 38118.016 | AN19: 0 | AO19: 745.8508 | AP19: 291.50548 | AQ19: 55022.734 | AR19: 25962.419 | AS19: 0 | AT19: 0 | AU19: 0 | AV19: 0 | AW19: 535.28454 | AX19: 348460.91 | AY19: 10694.819 | AZ19: 0 | BA19: 0 | BB19: 257550.02 | BC19: 9924.4877 | BD19: 117488.58 | BE19: 89253.783 | BF19: 47013.577 | BG19: 41893.707 | BH19: 14110.111 | BI19: 6379.8022 | BJ19: 110499.94 | BK19: 3175.2918 | BL19: 97662.775 | BM19: 11610.507 | BN19: 45971.782 | BO19: 171523.98 | BP19: 22228.126 | BQ19: 175608.55 | BR19: 0 | BS19: 26918.585 | BT19: 131389.24 | BU19: 172643.68 | BV19: 0 | BW19: 0 | BX19: 0 | BY19: 0 | BZ19: 548174.12 | CA19: 7593458.3 | CB19: 0 | CC19: 0 | CD19: 0 | CE19: 0 | CF19: 0 | CG19: 0 | CH19: 0 | CI19: 0 | CJ19: 0 | CK19: 0 | CL19: 0 | CM19: 0 | CN19: 0
A20: 332 | B20: 988309.15 | C20: 251803.55 | D20: 0 | E20: 229638.85 | F20: 3161.3423 | G20: 441042.38 | H20: 66019351 | I20: 7429611 | J20: 1347079.6 | K20: 557060.84 | L20: 42862279 | M20: 12647430 | N20: 4077363.6 | O20: 1787290.7 | P20: 4219436.4 | Q20: 24336753 | R20: 3082877.6 | S20: 2897800.4 | T20: 17768165 | U20: 995205.89 | V20: 154805.54 | W20: 22998974 | X20: 642340.93 | Y20: 490167.81 | Z20: 5944027.7 | AA20: 7626595.9 | AB20: 2141377.8 | AC20: 449344.88 | AD20: 286353.35 | AE20: 188361.38 | AF20: 913095.28 | AG20: 90385.16 | AH20: 160448.5 | AI20: 401563.07 | AJ20: 1616999.4 | AK20: 180695.9 | AL20: 414017.23 | AM20: 217958.54 | AN20: 774881.68 | AO20: 267563.16 | AP20: 9702.6833 | AQ20: 3429149.3 | AR20: 417920.05 | AS20: 332137.84 | AT20: 70946 | AU20: 0 | AV20: 803.82495 | AW20: 28846.256 | AX20: 212728.48 | AY20: 901550.32 | AZ20: 11221.872 | BA20: 1698690.1 | BB20: 3939792.6 | BC20: 560236.72 | BD20: 1574031.6 | BE20: 4042666.7 | BF20: 549826.29 | BG20: 392082.1 | BH20: 3224726.2 | BI20: 49435.988 | BJ20: 2522775.9 | BK20: 27099.68 | BL20: 431758.02 | BM20: 1784074.7 | BN20: 3279618.9 | BO20: 3563074.6 | BP20: 1656720.1 | BQ20: 1915023 | BR20: 265620.07 | BS20: 3077933.9 | BT20: 3515923.5 | BU20: 14473563 | BV20: 0 | BW20: 11375439 | BX20: 0 | BY20: 0 | BZ20: 10731761 | CA20: 25552622 | CB20: 0 | CC20: 0 | CD20: 0 | CE20: 0 | CF20: 0 | CG20: 0 | CH20: 0 | CI20: 513778.25 | CJ20: 0 | CK20: 0 | CL20: 0 | CM20: 42293.637 | CN20: 0
A21: 333 | B21: 117410.21 | C21: 32302.123 | D21: 0 | E21: 389196.84 | F21: 8827.1821 | G21: 148401.98 | H21: 19890761 | I21: 707133.52 | J21: 36385.317 | K21: 63604.347 | L21: 3241444.1 | M21: 9383556.2 | N21: 74353.848 | O21: 165160.6 | P21: 2712338.5 | Q21: 4239717.9 | R21: 45445.136 | S21: 173842.73 | T21: 1671657.5 | U21: 30816.42 | V21: 3232.8481 | W21: 1431410.7 | X21: 512637.16 | Y21: 7109.8038 | Z21: 1008500.4 | AA21: 1071820.4 | AB21: 1124300.1 | AC21: 221852.35 | AD21: 201597.7 | AE21: 151693.52 | AF21: 467856.51 | AG21: 1475.7123 | AH21: 22381.318 | AI21: 4648.9407 | AJ21: 244440.52 | AK21: 13965.131 | AL21: 10232.469 | AM21: 29530.088 | AN21: 1126402.7 | AO21: 15215.711 | AP21: 7883.0342 | AQ21: 339645.86 | AR21: 168805.91 | AS21: 5688.7597 | AT21: 15762.847 | AU21: 140952.02 | AV21: 0 | AW21: 62472.896 | AX21: 89853.056 | AY21: 347846.75 | AZ21: 14395.757 | BA21: 543938.15 | BB21: 879322.7 | BC21: 85839.054 | BD21: 853703.16 | BE21: 2280503.2 | BF21: 1834610.4 | BG21: 320281.37 | BH21: 1474648.8 | BI21: 318819.5 | BJ21: 291122.99 | BK21: 11819.859 | BL21: 160818.86 | BM21: 69579.396 | BN21: 650499.78 | BO21: 3091958.3 | BP21: 498569.36 | BQ21: 93293.006 | BR21: 59949.338 | BS21: 1821752.6 | BT21: 507033.79 | BU21: 5037592.1 | BV21: 0 | BW21: 84617116 | BX21: 0 | BY21: 0 | BZ21: 4246796.3 | CA21: 1.1443237e+08 | CB21: 0 | CC21: 0 | CD21: 0 | CE21: 0 | CF21: 0 | CG21: 0 | CH21: 0 | CI21: 60923.273 | CJ21: 0 | CK21: 0 | CL21: 0 | CM21: 4514472 | CN21: 0
... A82: Other | B82: 0 | C82: 0 | D82: 0 | E82: 0 | F82: 0 | G82: 0 | H82: 0 | I82: 0 | J82: 0 | K82: 0 | L82: 0 | M82: 0 | N82: 0 | O82: 0 | P82: 0 | Q82: 0 | R82: 0 | S82: 0 | T82: 0 | U82: 0 | V82: 0 | W82: 0 | X82: 0 | Y82: 0 | Z82: 0 | AA82: 0 | AB82: 0 | AC82: 0 | AD82: 0 | AE82: 0 | AF82: 0 | AG82: 0 | AH82: 0 | AI82: 0 | AJ82: 0 | AK82: 0 | AL82: 0 | AM82: 0 | AN82: 0 | AO82: 0 | AP82: 0 | AQ82: 0 | AR82: 0 | AS82: 0 | AT82: 0 | AU82: 0 | AV82: 0 | AW82: 0 | AX82: 0 | AY82: 0 | AZ82: 0 | BA82: 0 | BB82: 0 | BC82: 0 | BD82: 0 | BE82: 0 | BF82: 0 | BG82: 0 | BH82: 0 | BI82: 0 | BJ82: 0 | BK82: 0 | BL82: 0 | BM82: 0 | BN82: 0 | BO82: 0 | BP82: 0 | BQ82: 0 | BR82: 0 | BS82: 0 | BT82: 0 | BU82: -9.198994e+08 | BV82: 0 | BW82: 0 | BX82: 0 | BY82: 0 | BZ82: 0 | CA82: 9.5462556e+08 | CB82: 0 | CC82: 0 | CD82: 0 | CE82: 0 | CF82: 0 | CG82: 0 | CH82: 0 | CI82: 0 | CJ82: 0 | CK82: 0 | CL82: 0 | CM82: 0 | CN82: 0

Sheet Src_Stateior_SoI_TotUse
A1: State-of-Interest Total Use matrix at BEA Summary resolution, from
A2: EPA stateior. Rows = commodities, columns = industries + final demand
A3: categories (F01* PCE, F02* investment, F06* fed nondefense, F07* fed
A4: defense, F10* state and local, F040 intl exports, F050 intl imports).
A5: Values in nominal 2019 USD. This is the raw input used to compute
A6: DCS, ESoP, government/household expenditures, and Leontief coefficients.
A9: commodity | B9: 111CA | C9: 113FF | D9: 211 | E9: 212 | F9: 213 | G9: 22 | H9: 23 | I9: 321 | J9: 327 | K9: 331 | L9: 332 | M9: 333 | N9: 334 | O9: 335 | P9: 3361MV | Q9: 3364OT | R9: 337 | S9: 339 | T9: 311FT | U9: 313TT | V9: 315AL | W9: 322 | X9: 323 | Y9: 324 | Z9: 325 | AA9: 326 | AB9: 42 | AC9: 441 | AD9: 445 | AE9: 452 | AF9: 4A0 | AG9: 481 | AH9: 482 | AI9: 483 | AJ9: 484 | AK9: 485 | AL9: 486 | AM9: 487OS | AN9: 493 | AO9: 511 | AP9: 512 | AQ9: 513 | AR9: 514 | AS9: 521CI | AT9: 523 | AU9: 524 | AV9: 525 | AW9: HS | AX9: ORE | AY9: 532RL | AZ9: 5411 | BA9: 5415 | BB9: 5412OP | BC9: 55 | BD9: 561 | BE9: 562 | BF9: 61 | BG9: 621 | BH9: 622 | BI9: 623 | BJ9: 624 | BK9: 711AS | BL9: 713 | BM9: 721 | BN9: 722 | BO9: 81 | BP9: GFGD | BQ9: GFGN | BR9: GFE | BS9: GSLG | BT9: GSLE | BU9: F010 | BV9: F02S | BW9: F02E | BX9: F02N | BY9: F02R | BZ9: F030 | CA9: F040 | CB9: F050 | CC9: F06C | CD9: F06S | CE9: F06E | CF9: F06N | CG9: F07C | CH9: F07S | CI9: F07E | CJ9: F07N | CK9: F10C | CL9: F10S | CM9: F10E | CN9: F10N
A10: 111CA | B10: 98254954 | C10: 1670437.1 | D10: 0 | E10: 6150.7539 | F10: 71.665661 | G10: 0 | H10: 1602711.8 | I10: 0 | J10: 0 | K10: 0 | L10: 0 | M10: 0 | N10: 0 | O10: 0 | P10: 0 | Q10: 0 | R10: 0 | S10: 246546.2 | T10: 3.2913992e+08 | U10: 4183043.7 | V10: 0 | W10: 0 | X10: 0 | Y10: 0 | Z10: 12362163 | AA10: 0 | AB10: 890765.83 | AC10: 1400842.1 | AD10: 2466126.4 | AE10: 258715.97 | AF10: 689591.07 | AG10: 0 | AH10: 0 | AI10: 0 | AJ10: 0 | AK10: 0 | AL10: 0 | AM10: 37251.124 | AN10: 0 | AO10: 0 | AP10: 0 | AQ10: 0 | AR10: 0 | AS10: 1096.5782 | AT10: 0 | AU10: 0 | AV10: 0 | AW10: 0 | AX10: 4773.3049 | AY10: 0 | AZ10: 971.23553 | BA10: 0 | BB10: 1137134 | BC10: 34391.59 | BD10: 2348407.2 | BE10: 0 | BF10: 409391.08 | BG10: 0 | BH10: 0 | BI10: 0 | BJ10: 0 | BK10: 0 | BL10: 1136217.6 | BM10: 135127.8 | BN10: 14388224 | BO10: 24700.857 | BP10: 11976.33 | BQ10: -339492.11 | BR10: 0 | BS10: 6156385.1 | BT10: 0 | BU10: 2.2871645e+08 | BV10: 0 | BW10: 0 | BX10: 0 | BY10: 0 | BZ10: -32251624 | CA10: 97122377 | CB10: -1.8701706e+08 | CC10: 0 | CD10: 0 | CE10: 0 | CF10: 0 | CG10: 0 | CH10: 0 | CI10: 0 | CJ10: 0 | CK10: 0 | CL10: 0 | CM10: 0 | CN10: 0
A11: 113FF | B11: 66520192 | C11: 61737746 | D11: 0 | E11: 59064.682 | F11: 0 | G11: 0 | H11: 0 | I11: 91067005 | J11: 0 | K11: 0 | L11: 0 | M11: 0 | N11: 0 | O11: 0 | P11: 0 | Q11: 0 | R11: 188761.65 | S11: 430456.38 | T11: 27224640 | U11: 0 | V11: 630045.91 | W11: 33769696 | X11: 48908.044 | Y11: 0 | Z11: 645425.01 | AA11: 4870873.1 | AB11: 0 | AC11: 0 | AD11: 4066129.2 | AE11: 0 | AF11: 0 | AG11: 0 | AH11: 0 | AI11: 0 | AJ11: 0 | AK11: 0 | AL11: 0 | AM11: 2276.8778 | AN11: 0 | AO11: 0 | AP11: 0 | AQ11: 0 | AR11: 0 | AS11: 0 | AT11: 0 | AU11: 0 | AV11: 0 | AW11: 0 | AX11: 0 | AY11: 0 | AZ11: 0 | BA11: 0 | BB11: 758015.1 | BC11: 75592.084 | BD11: 5835.91 | BE11: 0 | BF11: 209687.31 | BG11: 0 | BH11: 0 | BI11: 0 | BJ11: 0 | BK11: 0 | BL11: 843303.36 | BM11: 2077861.3 | BN11: 20597766 | BO11: 256616.8 | BP11: 0 | BQ11: 198144.77 | BR11: 59009.526 | BS11: 15717621 | BT11: 0 | BU11: 32286117 | BV11: 0 | BW11: 0 | BX11: 0 | BY11: 0 | BZ11: 17611993 | CA11: 6.2552299e+08 | CB11: -74053919 | CC11: 0 | CD11: 0 | CE11: 0 | CF11: 0 | CG11: 0 | CH11: 0 | CI11: 0 | CJ11: 0 | CK11: 0 | CL11: 0 | CM11: 0 | CN11: 0
A12: 211 | B12: 0 | C12: 0 | D12: 0 | E12: 0 | F12: 26.652202 | G12: 4373512.3 | H12: 0 | I12: 8609.6142 | J12: 9.5635005 | K12: 5.2262033 | L12: 0 | M12: 0 | N12: 0 | O12: 0 | P12: 2.6231916 | Q12: 0 | R12: 0 | S12: 0 | T12: 15.881123 | U12: 0 | V12: 0 | W12: 13109.892 | X12: 11.179411 | Y12: 94810619 | Z12: 490543.77 | AA12: 0 | AB12: 2897.7329 | AC12: 4981.1376 | AD12: 0 | AE12: 20.111949 | AF12: 7967.7159 | AG12: 0 | AH12: 0 | AI12: 0 | AJ12: 0 | AK12: 0 | AL12: 1161.504 | AM12: 0 | AN12: 74948.891 | AO12: 23670.493 | AP12: 0 | AQ12: 1440.9807 | AR12: 2757.8492 | AS12: 0 | AT12: 0 | AU12: 0 | AV12: 0 | AW12: 0 | AX12: 23658.4 | AY12: 0 | AZ12: 0 | BA12: 9.8420318 | BB12: 2468.5702 | BC12: 3635.0351 | BD12: 0 | BE12: 4068.065 | BF12: 295420.06 | BG12: 17.015635 | BH12: 0 | BI12: 30.231059 | BJ12: 0 | BK12: 0 | BL12: 33383.44 | BM12: 26.06071 | BN12: 19.034557 | BO12: 6652.1049 | BP12: 0 | BQ12: 0 | BR12: 414048.77 | BS12: 0 | BT12: 2717109.1 | BU12: 0 | BV12: 0 | BW12: 0 | BX12: 0 | BY12: 0 | BZ12: 21036.313 | CA12: 329477.68 | CB12: -1.0251028e+08 | CC12: 0 | CD12: 0 | CE12: 0 | CF12: 0 | CG12: 0 | CH12: 0 | CI12: 0 | CJ12: 0 | CK12: 0 | CL12: 0 | CM12: 0 | CN12: 0
A13: 212 | B13: 1373774.1 | C13: 0 | D13: 0 | E13: 1740510.4 | F13: 527.24575 | G13: 6093991.1 | H13: 15454186 | I13: 25428.494 | J13: 8132509.3 | K13: 1348150.5 | L13: 666973.11 | M13: 82607.168 | N13: 7259.1809 | O13: 30353.698 | P13: 24508.627 | Q13: 237920.47 | R13: 12215.684 | S13: 110488.83 | T13: 2009248.6 | U13: 92406.365 | V13: 0 | W13: 6679173.5 | X13: 0 | Y13: 868769.63 | Z13: 5772347 | AA13: 144195.46 | AB13: 30125.845 | AC13: 0 | AD13: 0 | AE13: 0 | AF13: 5437.729 | AG13: 0 | AH13: 69037.712 | AI13: 0 | AJ13: 7249.1824 | AK13: 825.01913 | AL13: 0 | AM13: 851.99017 | AN13: 2317.4729 | AO13: 7462.9583 | AP13: 4117.827 | AQ13: 147271.64 | AR13: 186116.8 | AS13: 0 | AT13: 0 | AU13: 0 | AV13: 0 | AW13: 7561.4672 | AX13: 0 | AY13: 0 | AZ13: 0 | BA13: 0 | BB13: 1402671.1 | BC13: 44043.058 | BD13: 923821.66 | BE13: 73757.747 | BF13: 642689.6 | BG13: 0 | BH13: 42711.52 | BI13: 76784.608 | BJ13: 287878.84 | BK13: 221133.99 | BL13: 991494.71 | BM13: 296395.31 | BN13: 1088757.2 | BO13: 1424256.5 | BP13: 0 | BQ13: 3852247.5 | BR13: 0 | BS13: 4561601.1 | BT13: 3825114.8 | BU13: 433138.48 | BV13: 0 | BW13: 27948.034 | BX13: 0 | BY13: 0 | BZ13: 518595.07 | CA13: 14166548 | CB13: -12401859 | CC13: 0 | CD13: 0 | CE13: 0 | CF13: 0 | CG13: 0 | CH13: 0 | CI13: 0 | CJ13: 0 | CK13: 0 | CL13: 0 | CM13: 0 | CN13: 0
A14: 213 | B14: 0 | C14: 0 | D14: 0 | E14: 552391.05 | F14: 21815.075 | G14: 0 | H14: 0 | I14: 0 | J14: 0 | K14: 0 | L14: 0 | M14: 0 | N14: 0 | O14: 0 | P14: 0 | Q14: 0 | R14: 0 | S14: 0 | T14: 0 | U14: 0 | V14: 0 | W14: 0 | X14: 0 | Y14: 0 | Z14: 0 | AA14: 0 | AB14: 0 | AC14: 0 | AD14: 0 | AE14: 0 | AF14: 0 | AG14: 0 | AH14: 0 | AI14: 0 | AJ14: 0 | AK14: 0 | AL14: 0 | AM14: 0 | AN14: 0 | AO14: 0 | AP14: 0 | AQ14: 0 | AR14: 0 | AS14: 0 | AT14: 0 | AU14: 0 | AV14: 0 | AW14: 0 | AX14: 0 | AY14: 0 | AZ14: 0 | BA14: 0 | BB14: 46401.829 | BC14: 7100.0605 | BD14: 0 | BE14: 0 | BF14: 0 | BG14: 0 | BH14: 0 | BI14: 0 | BJ14: 0 | BK14: 0 | BL14: 0 | BM14: 0 | BN14: 0 | BO14: 0 | BP14: 0 | BQ14: 0 | BR14: 0 | BS14: 0 | BT14: 0 | BU14: 0 | BV14: 2667597.4 | BW14: 45405.442 | BX14: 0 | BY14: 0 | BZ14: -136.28849 | CA14: 56673.299 | CB14: -25836.968 | CC14: 0 | CD14: 0 | CE14: 0 | CF14: 0 | CG14: 0 | CH14: 0 | CI14: 0 | CJ14: 0 | CK14: 0 | CL14: 0 | CM14: 0 | CN14: 0
A15: 22 | B15: 6578474.9 | C15: 139950.84 | D15: 0 | E15: 763699.8 | F15: 1717.113 | G15: 23076583 | H15: 5889134.4 | I15: 3655554.1 | J15: 2086658.2 | K15: 483976.45 | L15: 4193866.9 | M15: 1090808.3 | N15: 692921.2 | O15: 118786.32 | P15: 460409.23 | Q15: 4926350.8 | R15: 385683.56 | S15: 484486.95 | T15: 8025259 | U15: 1462334.8 | V15: 73852.476 | W15: 18816071 | X15: 758174.85 | Y15: 1178509.6 | Z15: 7619558.6 | AA15: 3970883.8 | AB15: 11039138 | AC15: 5526648.3 | AD15: 16467532 | AE15: 8954414.1 | AF15: 16850426 | AG15: 246680.03 | AH15: 27180.529 | AI15: 39713.223 | AJ15: 3654525.6 | AK15: 256272.36 | AL15: 256223.66 | AM15: 859004.78 | AN15: 1994244.9 | AO15: 255063.08 | AP15: 78507.39 | AQ15: 2226252.7 | AR15: 657820.9 | AS15: 2281309.3 | AT15: 356482.59 | AU15: 605192.31 | AV15: 1246381.6 | AW15: 206702.13 | AX15: 21302998 | AY15: 674891.59 | AZ15: 402361.2 | BA15: 474452 | BB15: 3665802.1 | BC15: 4919911.1 | BD15: 2458798.9 | BE15: 1506096.1 | BF15: 6070725.5 | BG15: 4052653 | BH15: 13305106 | BI15: 6382185.6 | BJ15: 1833369.2 | BK15: 642913.14 | BL15: 3591244.1 | BM15: 9009750.5 | BN15: 21257313 | BO15: 6289563.2 | BP15: 1282792.9 | BQ15: 1649924.9 | BR15: 3136960.2 | BS15: 20559655 | BT15: 1984627 | BU15: 2.716927e+08 | BV15: 0 | BW15: 0 | BX15: 0 | BY15: 0 | BZ15: 0 | CA15: 12635456 | CB15: -7485798.9 | CC15: 0 | CD15: 0 | CE15: 0 | CF15: 0 | CG15: 0 | CH15: 0 | CI15: 0 | CJ15: 0 | CK15: 0 | CL15: 0 | CM15: 0 | CN15: 0
A16: 23 | B16: 4379271 | C16: 214192.62 | D16: 0 | E16: 2518119.8 | F16: 24335.627 | G16: 17795763 | H16: 730183.57 | I16: 2675754.9 | J16: 1881466.6 | K16: 406334.33 | L16: 4878604.9 | M16: 1592331.5 | N16: 966698.84 | O16: 102523.64 | P16: 482982.29 | Q16: 2939289.8 | R16: 339010.66 | S16: 681162.34 | T16: 7239795.2 | U16: 747121.97 | V16: 64310.219 | W16: 14407772 | X16: 794148.68 | Y16: 6547371.2 | Z16: 4650424.4 | AA16: 2613576.5 | AB16: 11122400 | AC16: 6777846.6 | AD16: 6970338 | AE16: 8937081.6 | AF16: 14953641 | AG16: 227159.26 | AH16: 3775144 | AI16: 42889.361 | AJ16: 1720957.4 | AK16: 1256735.9 | AL16: 649669.74 | AM16: 2873419.8 | AN16: 2802453.3 | AO16: 165419.36 | AP16: 50208.369 | AQ16: 3419844.5 | AR16: 675697.66 | AS16: 16365820 | AT16: 1928214.9 | AU16: 3058479.1 | AV16: 234529.91 | AW16: 3.5461019e+08 | AX16: 1.0118648e+08 | AY16: 1783177.6 | AZ16: 465353.05 | BA16: 176419.93 | BB16: 5862375.9 | BC16: 3072913.2 | BD16: 2833334.3 | BE16: 595315.44 | BF16: 8675850.5 | BG16: 2850505.5 | BH16: 8129534.5 | BI16: 4482352.7 | BJ16: 3378220.5 | BK16: 573992.41 | BL16: 2533676.6 | BM16: 17272728 | BN16: 10164311 | BO16: 12821503 | BP16: 12641294 | BQ16: 2488321.5 | BR16: 3002536.7 | BS16: 1.2462392e+08 | BT16: 1.2360929e+08 | BU16: 0 | BV16: 1.3796043e+09 | BW16: 0 | BX16: 0 | BY16: 2.5193233e+09 | BZ16: 0 | CA16: 272315.82 | CB16: 0 | CC16: 0 | CD16: 0 | CE16: 0 | CF16: 0 | CG16: 0 | CH16: 1.9174801e+08 | CI16: 0 | CJ16: 0 | CK16: 0 | CL16: 8.0841103e+08 | CM16: 0 | CN16: 0
A17: 321 | B17: 1114467.3 | C17: 427669.42 | D17: 0 | E17: 77837.411 | F17: 1860.931 | G17: 10233.297 | H17: 76924988 | I17: 1.4694782e+08 | J17: 267641.67 | K17: 114820.87 | L17: 468700.8 | M17: 963419.1 | N17: 344553 | O17: 262684.58 | P17: 1216682.9 | Q17: 934156.46 | R17: 10945262 | S17: 1638566.8 | T17: 914819.39 | U17: 280776.88 | V17: 0 | W17: 37497355 | X17: 2473.9834 | Y17: 0 | Z17: 394719.45 | AA17: 4316472.8 | AB17: 12437094 | AC17: 473163.85 | AD17: 2766897.5 | AE17: 460674.24 | AF17: 2606274 | AG17: 0 | AH17: 2492392.7 | AI17: 0 | AJ17: 381443.18 | AK17: 0 | AL17: 4706.8101 | AM17: 86384.39 | AN17: 283492.41 | AO17: 34752.27 | AP17: 38233.114 | AQ17: 759670.96 | AR17: 549372.14 | AS17: 498861.93 | AT17: 5076.0837 | AU17: 0 | AV17: 0 | AW17: 67262.449 | AX17: 12231493 | AY17: 575557.74 | AZ17: 23840.333 | BA17: 58748.412 | BB17: 1425158.5 | BC17: 11988.193 | BD17: 2087140.4 | BE17: 91681.887 | BF17: 113298.8 | BG17: 1039224.1 | BH17: 2282018.5 | BI17: 24500.478 | BJ17: 2404186.2 | BK17: 11510.544 | BL17: 465121.34 | BM17: 3921459.4 | BN17: 2518838.6 | BO17: 883227.02 | BP17: 23567.481 | BQ17: 136752 | BR17: 9858.0696 | BS17: 6196394.3 | BT17: 479408.46 | BU17: 13458603 | BV17: 1209919.2 | BW17: 0 | BX17: 0 | BY17: 20943405 | BZ17: 3851292.2 | CA17: 45307964 | CB17: -88136896 | CC17: 0 | CD17: 0 | CE17: 0 | CF17: 0 | CG17: 0 | CH17: 0 | CI17: 253.63788 | CJ17: 0 | CK17: 0 | CL17: 0 | CM17: 0 | CN17: 0
A18: 327 | B18: 35273.88 | C18: 408104.72 | D18: 0 | E18: 220986.58 | F18: 6591.2076 | G18: 116766.43 | H18: 1.2457894e+08 | I18: 5600183.8 | J18: 21353347 | K18: 553542.59 | L18: 3927568.4 | M18: 2121474.2 | N18: 395320.12 | O18: 751083.12 | P18: 2823017.8 | Q18: 1423228.4 | R18: 622353.18 | S18: 1150580.3 | T18: 9701810.8 | U18: 136166.17 | V18: 0 | W18: 4058573.9 | X18: 1604.6711 | Y18: 853497.44 | Z18: 2270812 | AA18: 4267197 | AB18: 184098.4 | AC18: 738061.85 | AD18: 243684.08 | AE18: 866772.06 | AF18: 1606188.9 | AG18: 0 | AH18: 16127.129 | AI18: 0 | AJ18: 280899.51 | AK18: 0 | AL18: 0 | AM18: 21598.881 | AN18: 190649.94 | AO18: 1521.9012 | AP18: 446.11055 | AQ18: 2707654 | AR18: 369693.44 | AS18: 61533.666 | AT18: 24158.7 | AU18: 109459.1 | AV18: 0 | AW18: 306510.88 | AX18: 109545.44 | AY18: 857156.62 | AZ18: 0 | BA18: 266589.95 | BB18: 8124126.1 | BC18: 116640.63 | BD18: 1868928.4 | BE18: 887207.01 | BF18: 241463.59 | BG18: 5880334.9 | BH18: 12945619 | BI18: 665193.17 | BJ18: 1680279.9 | BK18: 19562.269 | BL18: 396443.86 | BM18: 411949.07 | BN18: 7096660.5 | BO18: 3582271.1 | BP18: 67010.856 | BQ18: 1811907 | BR18: 0 | BS18: 4546008.3 | BT18: 4592933.8 | BU18: 40565845 | BV18: 0 | BW18: 0 | BX18: 0 | BY18: 0 | BZ18: 2429950.5 | CA18: 1698594.3 | CB18: -85050788 | CC18: 0 | CD18: 0 | CE18: 0 | CF18: 0 | CG18: 0 | CH18: 0 | CI18: 0 | CJ18: 0 | CK18: 0 | CL18: 0 | CM18: 0 | CN18: 0
A19: 331 | B19: 165177.31 | C19: 0 | D19: 0 | E19: 104051.02 | F19: 2254.2935 | G19: 1303.3367 | H19: 5131620.9 | I19: 814901.53 | J19: 939823.16 | K19: 12326264 | L19: 72329359 | M19: 17857503 | N19: 3789515.4 | O19: 2990341.5 | P19: 7223459.1 | Q19: 15562204 | R19: 2635587.8 | S19: 4456632.7 | T19: 2513525.1 | U19: 101831.1 | V19: 0 | W19: 4219103.2 | X19: 11993.039 | Y19: 5454.2957 | Z19: 57231.997 | AA19: 1505299.5 | AB19: 515186.74 | AC19: 11965.302 | AD19: 0 | AE19: 0 | AF19: 1275474.4 | AG19: 0 | AH19: 199114.69 | AI19: 0 | AJ19: 0 | AK19: 0 | AL19: 0 | AM19: 67717.427 | AN19: 0 | AO19: 6611.7857 | AP19: 3042.649 | AQ19: 171217.12 | AR19: 192498 | AS19: 0 | AT19: 0 | AU19: 0 | AV19: 0 | AW19: 535.28454 | AX19: 2433788.7 | AY19: 72377.062 | AZ19: 0 | BA19: 0 | BB19: 1714010.7 | BC19: 78371.559 | BD19: 703997.54 | BE19: 465881.92 | BF19: 331326.45 | BG19: 286653.1 | BH19: 52157.855 | BI19: 39830.196 | BJ19: 620838.66 | BK19: 23922.006 | BL19: 490320.66 | BM19: 86583.95 | BN19: 138642.67 | BO19: 1225391.4 | BP19: 248439.43 | BQ19: 891174.09 | BR19: 0 | BS19: 102060.06 | BT19: 561771.84 | BU19: 1032356.5 | BV19: 0 | BW19: 0 | BX19: 0 | BY19: 0 | BZ19: 759181.17 | CA19: 7593458.3 | CB19: -1.2548359e+08 | CC19: 0 | CD19: 0 | CE19: 0 | CF19: 0 | CG19: 0 | CH19: 0 | CI19: 0 | CJ19: 0 | CK19: 0 | CL19: 0 | CM19: 0 | CN19: 0
A20: 332 | B20: 3011933.1 | C20: 666801.75 | D20: 0 | E20: 340467.79 | F20: 4649.3022 | G20: 1397407.1 | H20: 1.0125459e+08 | I20: 11625874 | J20: 1622209.7 | K20: 659993.73 | L20: 57689753 | M20: 19295930 | N20: 5355730.4 | O20: 2254869.6 | P20: 6767284.1 | Q20: 34954188 | R20: 4750307.8 | S20: 3849009.3 | T20: 25229371 | U20: 1288946.1 | V20: 154805.54 | W20: 33565547 | X20: 726456.36 | Y20: 545169.73 | Z20: 9350307 | AA20: 10583145 | AB20: 3183833.6 | AC20: 785028.47 | AD20: 722852.01 | AE20: 295179.09 | AF20: 4248877 | AG20: 92482.014 | AH20: 313494.87 | AI20: 433059.95 | AJ20: 2569499.3 | AK20: 447476.67 | AL20: 429283.62 | AM20: 443369.44 | AN20: 1254859.9 | AO20: 315663.83 | AP20: 12453.827 | AQ20: 8148649.5 | AR20: 606978.89 | AS20: 547690.3 | AT20: 99254.067 | AU20: 0 | AV20: 70205.534 | AW20: 38949.974 | AX20: 2645219.9 | AY20: 1447344.7 | AZ20: 44631.835 | BA20: 2545941.3 | BB20: 6504429.9 | BC20: 1010546.4 | BD20: 3747908.1 | BE20: 6618317.1 | BF20: 907371.27 | BG20: 602951.73 | BH20: 4632492.7 | BI20: 82886.382 | BJ20: 7076994.3 | BK20: 45541.203 | BL20: 1155075.2 | BM20: 4581160.9 | BN20: 6801112.5 | BO20: 7335853.9 | BP20: 5394893.6 | BQ20: 2879882.3 | BR20: 515126.64 | BS20: 6613161.3 | BT20: 5282196.6 | BU20: 47751599 | BV20: 0 | BW20: 26049008 | BX20: 0 | BY20: 0 | BZ20: 12843090 | CA20: 25552622 | CB20: -2.0968228e+08 | CC20: 0 | CD20: 0 | CE20: 0 | CF20: 0 | CG20: 0 | CH20: 0 | CI20: 699057.38 | CJ20: 0 | CK20: 0 | CL20: 0 | CM20: 389160.41 | CN20: 0
A21: 333 | B21: 5034787.7 | C21: 233107.7 | D21: 0 | E21: 1641419.9 | F21: 29966.777 | G21: 3232754.9 | H21: 45501561 | I21: 2142697.3 | J21: 140088.2 | K21: 162296.56 | L21: 9656809.5 | M21: 35538118 | N21: 503997.78 | O21: 757782.78 | P21: 11445494 | Q21: 12371087 | R21: 150915.12 | S21: 996074.19 | T21: 9392934.2 | U21: 101058.66 | V21: 3232.8481 | W21: 11132731 | X21: 1920333.7 | Y21: 34253.608 | Z21: 5391088 | AA21: 3278911.1 | AB21: 4208590.8 | AC21: 542726.36 | AD21: 433487.62 | AE21: 254060.49 | AF21: 1686623.7 | AG21: 2174.6638 | AH21: 37840.548 | AI21: 33465.23 | AJ21: 799796.38 | AK21: 66880.325 | AL21: 32849.344 | AM21: 10054623 | AN21: 2578723.8 | AO21: 39852.637 | AP21: 9258.6059 | AQ21: 896231.3 | AR21: 201567.01 | AS21: 8383.1653 | AT21: 20117.935 | AU21: 1774673.8 | AV21: 0 | AW21: 67524.755 | AX21: 99235.858 | AY21: 658127.12 | AZ21: 19168.609 | BA21: 3394971.3 | BB21: 4155141.4 | BC21: 752297.38 | BD21: 8093149.5 | BE21: 13846632 | BF21: 4595891.5 | BG21: 2233170.1 | BH21: 2635105 | BI21: 445930.99 | BJ21: 457537.79 | BK21: 30261.382 | BL21: 396413.59 | BM21: 213759.09 | BN21: 1328682.2 | BO21: 11721117 | BP21: 1129180.8 | BQ21: 665745.44 | BR21: 161443.54 | BS21: 9729498 | BT21: 3724250.3 | BU21: 30446204 | BV21: 0 | BW21: 2.4066289e+08 | BX21: 0 | BY21: 0 | BZ21: 6197835 | CA21: 1.1443237e+08 | CB21: -3.8219118e+08 | CC21: 0 | CD21: 0 | CE21: 0 | CF21: 0 | CG21: 0 | CH21: 0 | CI21: 200182.43 | CJ21: 0 | CK21: 0 | CL21: 0 | CM21: 15975330 | CN21: 0
... A82: Other | B82: 2670496.6 | C82: 240966.7 | D82: 0 | E82: 14393.369 | F82: 3926.8053 | G82: 4784898.5 | H82: 3927973.3 | I82: 1715880.9 | J82: 626450.06 | K82: 241333.29 | L82: 2522935.7 | M82: 2345414.7 | N82: 4467240.3 | O82: 200306.3 | P82: 1303239.5 | Q82: 3125911.4 | R82: 293809.24 | S82: 888735.48 | T82: 7773993.6 | U82: 619408.81 | V82: 160775.55 | W82: 7538188 | X82: 606125.94 | Y82: 4731593.6 | Z82: 5138578.6 | AA82: 2108644.9 | AB82: 20719885 | AC82: 557827.14 | AD82: 2946365.9 | AE82: 3694112.4 | AF82: 13493494 | AG82: 11799001 | AH82: 200969.99 | AI82: 1252503.4 | AJ82: 3206211.4 | AK82: 46300.795 | AL82: 120434.86 | AM82: 1102008.8 | AN82: 272503.75 | AO82: 816538.13 | AP82: 354897.51 | AQ82: 8800648.6 | AR82: 563081.39 | AS82: 10753373 | AT82: 42164866 | AU82: 5509061.7 | AV82: 476239.32 | AW82: 116192.76 | AX82: 2404343 | AY82: 2880373.8 | AZ82: 505922.29 | BA82: 4377827.8 | BB82: 8110391.3 | BC82: 6805079.9 | BD82: 4158085.9 | BE82: 453573.67 | BF82: 1865264.8 | BG82: 0 | BH82: 0 | BI82: 2087304.5 | BJ82: 0 | BK82: 799901.07 | BL82: 963045.12 | BM82: 3956290.9 | BN82: 8508872.2 | BO82: 13581345 | BP82: 11142487 | BQ82: 8697583.8 | BR82: 16915.7 | BS82: 0 | BT82: 0 | BU82: -3.3469937e+08 | BV82: 0 | BW82: 0 | BX82: 44346109 | BY82: 0 | BZ82: 0 | CA82: 9.5462556e+08 | CB82: -8.9787849e+08 | CC82: 0 | CD82: 0 | CE82: 0 | CF82: 0 | CG82: 0 | CH82: 0 | CI82: 0 | CJ82: 0 | CK82: 0 | CL82: 0 | CM82: 0 | CN82: 0

Sheet Src_Disagg_EIA_coal
A1: Raw EIA Annual Coal Report (Form EIA-7A) 2019 state production values,
A2: used as the numerator for the 212 BEA mining disagg split (05 coal vs
A3: 07T08 other mining). Source:
A4: https://www.eia.gov/coal/annual/
A6: THIS STATE: ME
A9: state | B9: short_tons | C9: short_tons_units | D9: value_usd | E9: source_notes
A10: AL | B10: 12031000 | C10: short tons | D10: 600000000 | E10: EIA Annual Coal Report 2019; AL avg ~$50/ton bituminous
A11: AK | B11: 1000000 | C11: short tons | D11: 40000000 | E11: EIA Annual Coal Report 2019; AK Usibelli ~$40/ton subbit
A12: AZ | B12: 4220000 | C12: short tons | D12: 125000000 | E12: EIA Annual Coal Report 2019; Kayenta mine closed 2019; partial year
A13: AR | B13: 0 | C13: short tons | D13: 0
A14: CA | B14: 0 | C14: short tons | D14: 0
A15: CO | B15: 10710000 | C15: short tons | D15: 330000000 | E15: EIA ~$31/ton
A16: CT | B16: 0 | C16: short tons | D16: 0
A17: DE | B17: 0 | C17: short tons | D17: 0
A18: DC | B18: 0 | C18: short tons | D18: 0
A19: FL | B19: 0 | C19: short tons | D19: 0
A20: GA | B20: 0 | C20: short tons | D20: 0
A21: HI | B21: 0 | C21: short tons | D21: 0
A22: ID | B22: 0 | C22: short tons | D22: 0
A23: IL | B23: 45919000 | C23: short tons | D23: 1950000000 | E23: IL Basin avg ~$42/ton
A24: IN | B24: 28820000 | C24: short tons | D24: 1210000000 | E24: IL Basin avg ~$42/ton
A25: IA | B25: 0 | C25: short tons | D25: 0
A26: KS | B26: 0 | C26: short tons | D26: 0
A27: KY | B27: 36140000 | C27: short tons | D27: 1730000000 | E27: KY split East (Central App ~$58/ton) + West (IL Basin ~$40/ton)
A28: LA | B28: 2720000 | C28: short tons | D28: 60000000 | E28: lignite ~$22/ton
A29: ME | B29: 0 | C29: short tons | D29: 0
A30: MD | B30: 1320000 | C30: short tons | D30: 70000000 | E30: NA Appalachia ~$55/ton
A31: MA | B31: 0 | C31: short tons | D31: 0
A32: MI | B32: 0 | C32: short tons | D32: 0
A33: MN | B33: 0 | C33: short tons | D33: 0
A34: MS | B34: 2800000 | C34: short tons | D34: 65000000 | E34: lignite
A35: MO | B35: 264000 | C35: short tons | D35: 12000000
A36: MT | B36: 38660000 | C36: short tons | D36: 590000000 | E36: PRB subbit ~$14/ton + some bituminous
A37: NE | B37: 0 | C37: short tons | D37: 0
A38: NV | B38: 0 | C38: short tons | D38: 0
A39: NH | B39: 0 | C39: short tons | D39: 0
A40: NJ | B40: 0 | C40: short tons | D40: 0
A41: NM | B41: 10720000 | C41: short tons | D41: 260000000 | E41: San Juan + McKinley ~$24/ton
A42: NY | B42: 0 | C42: short tons | D42: 0
A43: NC | B43: 0 | C43: short tons | D43: 0
...

Sheet Src_Disagg_heuristics
A1: Hand-curated heuristic tables used as layer-3 fallback for BEA 327
A2: (nonmetallic) / 331 (primary metals) / 325 (chemicals) disaggregation
A3: when Census ASM is suppressed and GHGRP lacks coverage.
A5: Sources:
A6: - cement-heavy state list: GHGRP Subpart H 2019 facility presence
A7: + USGS Minerals Yearbook 2019 cement production rankings
A8: - glass-heavy state list: Census ASM 2017 NAICS 3272 top-6 states
A9: - steel_share: Census ASM 2017 NAICS 331 VA breakdown (2021 SUSB
A10: supplement where suppressed) + industry knowledge
A11: - pharma_share: Census ASM 2017 NAICS 325 VA breakdown +
A12: BLS QCEW 2019 NAICS 3254 employment share
A14: See R/build_state_overrides.R for the applied logic.
... A23: 331 / 325 heuristic split shares (used only where Census ASM / GHGRP unavailable):
A25: state | B25: 331_steel_share (-> ISIC 241) | C25: 331_other_share (-> ISIC 242) | D25: 325_pharma_share (-> ISIC 21) | E25: 325_chem_share (-> ISIC 20)
A26: AK | B26: 0.4 | C26: 0.6 | D26: 0.3 | E26: 0.7
A27: AL | B27: 0.7 | C27: 0.3 | D27: 0.15 | E27: 0.85
A28: AR | B28: 0.5 | C28: 0.5 | D28: 0.1 | E28: 0.9
A29: AZ | B29: 0.3 | C29: 0.7 | D29: 0.2 | E29: 0.8
A30: CA | B30: 0.35 | C30: 0.65 | D30: 0.55 | E30: 0.45
A31: CO | B31: 0.5 | C31: 0.5 | D31: 0.3 | E31: 0.7
A32: CT | B32: 0.4 | C32: 0.6 | D32: 0.5 | E32: 0.5
A33: DC | B33: 0.4 | C33: 0.6 | D33: 0.3 | E33: 0.7
A34: DE | B34: 0.5 | C34: 0.5 | D34: 0.4 | E34: 0.6
A35: FL | B35: 0.35 | C35: 0.65 | D35: 0.4 | E35: 0.6
A36: GA | B36: 0.5 | C36: 0.5 | D36: 0.3 | E36: 0.7
A37: HI | B37: 0.4 | C37: 0.6 | D37: 0.3 | E37: 0.7
... A76: WY | B76: 0.3 | C76: 0.7 | D76: 0.1 | E76: 0.9

Sheet Crosswalk_BEA_to_ISIC
A1: BEA Summary (post-disagg) -> 42-ISIC crosswalk, applied to state ME.
A3: Rows with allocation_weight != 1.0 represent BEA sectors that are split
A4: across multiple ISIC codes (e.g. BEA 22 utilities -> 351/352T353/36T39).
A5: State-specific overrides are loaded from crosswalks/state_overrides/<ST>/splits.csv.
A8: BEA_code | B8: BEA_name | C8: ISIC_code | D8: ISIC_name | E8: allocation_weight | F8: notes | G8: source
A9: 111CA | B9: Farms | C9: 01T03 | D9: Agriculture, forestry, fishing | E9: 1
A10: 113FF | B10: Forestry, fishing, related | C10: 01T03 | D10: Agriculture, forestry, fishing | E10: 1
A11: 211 | B11: Oil and gas extraction | C11: 06 | D11: Extraction of crude petroleum and natural gas | E11: 1
A12: 213 | B12: Support activities for mining | C12: 09 | D12: Mining support service activities | E12: 1
A13: 22 | B13: Utilities | C13: 351 | D13: Electricity | E13: 0.72 | F13: BEA 2012 Detail: electric ~72% of 22 output
A14: 22 | B14: Utilities | C14: 352T353 | D14: Gas, steam, AC | E14: 0.2 | F14: BEA Detail: gas distribution ~20%
A15: 22 | B15: Utilities | C15: 36T39 | D15: Water, sewerage, waste | E15: 0.08 | F15: BEA Detail: water/sewage ~8%
A16: 23 | B16: Construction | C16: 41T43 | D16: Construction | E16: 1
A17: 311FT | B17: Food, beverage, tobacco | C17: 10T12 | D17: Food, beverages, tobacco | E17: 1
A18: 313TT | B18: Textile mills and textile product mills | C18: 13T15 | D18: Textiles, apparel, leather | E18: 1
A19: 315AL | B19: Apparel and leather | C19: 13T15 | D19: Textiles, apparel, leather | E19: 1
A20: 321 | B20: Wood products | C20: 16 | D20: Wood and products of wood and cork | E20: 1
A21: 322 | B21: Paper products | C21: 17T18 | D21: Paper products and printing | E21: 1
A22: 323 | B22: Printing and related | C22: 17T18 | D22: Paper products and printing | E22: 1
A23: 324 | B23: Petroleum and coal products | C23: 19 | D23: Coke and refined petroleum products | E23: 0.961 | F23: BEA 2024 Detail: 324110 refineries + 324121/324122 asphalt = ~96.1% of 324 output ($601,241M / $625,936M)
A24: 324 | B24: Petroleum and coal products | C24: 241 | D24: Iron and steel (incl. coal coking) | E24: 0.039 | F24: EPS modeling convention: route NAICS 324190 (Other petroleum and coal products mfg, includes coal coking) to 241 to consolidate coke with iron and steel; matches eps-us national model
A25: 326 | B25: Plastics and rubber products | C25: 22 | D25: Rubber and plastics products | E25: 1
A26: 332 | B26: Fabricated metal products | C26: 25 | D26: Fabricated metal products | E26: 1
A27: 333 | B27: Machinery | C27: 28 | D27: Machinery and equipment n.e.c. | E27: 1
A28: 334 | B28: Computer and electronic products | C28: 26 | D28: Computer, electronic and optical products | E28: 1
A29: 335 | B29: Electrical equipment, appliances | C29: 27 | D29: Electrical equipment | E29: 1
A30: 3361MV | B30: Motor vehicles, bodies, trailers, parts | C30: 29 | D30: Motor vehicles, trailers, semi-trailers | E30: 1
A31: 3364OT | B31: Other transportation equipment | C31: 30 | D31: Other transport equipment | E31: 1
A32: 337 | B32: Furniture and related products | C32: 31T33 | D32: Furniture; other manufacturing; repair | E32: 1
A33: 339 | B33: Miscellaneous manufacturing | C33: 31T33 | D33: Furniture; other manufacturing; repair | E33: 1
A34: 42 | B34: Wholesale trade | C34: 45T47 | D34: Wholesale and retail trade | E34: 1
A35: 441 | B35: Motor vehicle and parts dealers | C35: 45T47 | D35: Wholesale and retail trade | E35: 1
A36: 445 | B36: Food and beverage stores | C36: 45T47 | D36: Wholesale and retail trade | E36: 1
... A43: 485 | B43: Transit and ground passenger | C43: 49T53 | D43: Transportation and storage | E43: 1
A44: 486 | B44: Pipeline transportation | C44: 352T353 | D44: Gas, steam, AC (incl. pipelines per EPS energy-side convention) | E44: 1 | F44: Reclassified from 49T53 (staff decision 2026-07-16): EPS 352T353 = 'energy pipelines and gas processing'; industrial-energy side sources pipeline fuel (AEO T36 / NAICS 486) here, so IO dollars follow. NOTE: diverges from eps-us national io-model (tags 486 -> 49T53); national files to be corrected separately.
A45: 487OS | B45: Other transportation and support | C45: 49T53 | D45: Transportation and storage | E45: 1
A46: 493 | B46: Warehousing and storage | C46: 49T53 | D46: Transportation and storage | E46: 1
A47: 511 | B47: Publishing industries (incl software) | C47: 58T60 | D47: Publishing, audiovisual, broadcasting | E47: 1
A48: 512 | B48: Motion picture and sound recording | C48: 58T60 | D48: Publishing, audiovisual, broadcasting | E48: 1
A49: 513 | B49: Broadcasting and telecom | C49: 58T60 | D49: Publishing, audiovisual, broadcasting | E49: 0.25 | F49: Placeholder ~25/75 broadcast/telecom per \u00a74.6
...

Sheet State_disagg_splits
A1: State-specific disaggregation ratios applied for ME.
A3: Five BEA Summary sectors are split into finer ISIC children. Ratios
A4: come from the layered proxy strategy in the migration plan (sec 4.0):
A5: 1. Pulled-from-source data (EIA-7A, Census ASM, GHGRP) where available
A6: 2. GHGRP emissions proxy where Census is suppressed
A7: 3. Hand-curated heuristic table (from industry knowledge)
A8: 4. National fallback ratio (last resort)
A11: BEA_code | B11: ISIC_code | C11: allocation_weight | D11: source
A12: 212 | B12: 05 | C12: 0 | D12: coal/(coal+nonfuel) mine-value share, 2012 USD: EIA coal 2019 $0M + USGS T3 nonfuel 2021 $98M [nonfuel partial total] -> coal share 0.000 (applied to stateior 212 $76M)
A13: 212 | B13: 07T08 | C13: 1 | D13: coal/(coal+nonfuel) mine-value share, 2012 USD: EIA coal 2019 $0M + USGS T3 nonfuel 2021 $98M [nonfuel partial total] -> coal share 0.000 (applied to stateior 212 $76M)
A14: 327 | B14: 231 | C14: 0.25 | D14: HEURISTIC (GHGRP Subpart H cement state list + glass industry profile; Census ASM suppressed or missing)
A15: 327 | B15: 239 | C15: 0.75 | D15: HEURISTIC (GHGRP Subpart H cement state list + glass industry profile; Census ASM suppressed or missing)
A16: 331 | B16: 241 | C16: 0.4 | D16: HEURISTIC (no ASM or GHGRP data pulled yet)
A17: 331 | B17: 242 | C17: 0.6 | D17: HEURISTIC (no ASM or GHGRP data pulled yet)
A18: 325 | B18: 20 | C18: 0.75 | D18: HEURISTIC (Census ASM suppressed or unpulled)
A19: 325 | B19: 21 | C19: 0.25 | D19: HEURISTIC (Census ASM suppressed or unpulled)

Sheet NAICS_to_ISIC_Key
A1: Concise NAICS Summary -> ISIC Rev 4 mapping used by this pipeline.
A2: See US Census Bureau NAICS 2017 to ISIC Rev 4 concordance for the full
A3: detail-level mapping:
A4: https://www.census.gov/naics/concordances/2017_NAICS_to_ISIC_4.xlsx
A7: ISIC Rev 4 code | B7: Title (42-ISIC scheme) | C7: BEA Summary sources (examples)
A8: 01T03 | B8: Agriculture, forestry and fishing | C8: 111CA Farms; 113FF Forestry/fishing/related
A9: 05 | B9: Mining of coal and lignite | C9: 212/coal (NAICS 2121)
A10: 06 | B10: Extraction of crude petroleum and natural gas | C10: 211 Oil and gas extraction
A11: 07T08 | B11: Mining of metal ores; other mining and quarrying | C11: 212/other (NAICS 2122+2123)
A12: 09 | B12: Mining support service activities | C12: 213 Support activities for mining
A13: 10T12 | B13: Food products, beverages and tobacco | C13: 311FT Food/beverage/tobacco
A14: 13T15 | B14: Textiles, wearing apparel, leather and related products | C14: 313TT Textile mills; 315AL Apparel/leather
A15: 16 | B15: Wood and products of wood and cork, except furniture | C15: 321 Wood products
A16: 17T18 | B16: Paper products and printing | C16: 322 Paper; 323 Printing
A17: 19 | B17: Coke and refined petroleum products | C17: 324 Petroleum and coal products
A18: 20 | B18: Chemicals and chemical products (excl. pharmaceuticals) | C18: 325/chem (NAICS 3251-3259 excl. 3254)
... A49: 97T98 | B49: Households as employers; undifferentiated production (zero in EPS) | C49: Designed zero row: households as employers (NAICS 814)

Sheet 6_Calc_DCS_num_ISIC
A1: STEP 1 - read BEA code / ISIC code / weight live from the Crosswalk tab, pull each BEA value from the source tab, then weight it
A2: BEA_code | B2: ISIC_code | C2: allocation_weight | D2: BEA_value_nominal | E2: weighted_nominal
A3: ='Crosswalk_BEA_to_ISIC'!A9 | B3: ='Crosswalk_BEA_to_ISIC'!C9 | C3: ='Crosswalk_BEA_to_ISIC'!E9 | D3: =IFERROR(INDEX('1_DCS_numerator_by_BEA'!$B$2:$B$74, MATCH($A3, '1_DCS_numerator_by_BEA'!$A$2:$A$74, 0)), 0) | E3: =C3*D3
A4: ='Crosswalk_BEA_to_ISIC'!A10 | B4: ='Crosswalk_BEA_to_ISIC'!C10 | C4: ='Crosswalk_BEA_to_ISIC'!E10 | D4: =IFERROR(INDEX('1_DCS_numerator_by_BEA'!$B$2:$B$74, MATCH($A4, '1_DCS_numerator_by_BEA'!$A$2:$A$74, 0)), 0) | E4: =C4*D4
A5: ='Crosswalk_BEA_to_ISIC'!A11 | B5: ='Crosswalk_BEA_to_ISIC'!C11 | C5: ='Crosswalk_BEA_to_ISIC'!E11 | D5: =IFERROR(INDEX('1_DCS_numerator_by_BEA'!$B$2:$B$74, MATCH($A5, '1_DCS_numerator_by_BEA'!$A$2:$A$74, 0)), 0) | E5: =C5*D5
A6: ='Crosswalk_BEA_to_ISIC'!A12 | B6: ='Crosswalk_BEA_to_ISIC'!C12 | C6: ='Crosswalk_BEA_to_ISIC'!E12 | D6: =IFERROR(INDEX('1_DCS_numerator_by_BEA'!$B$2:$B$74, MATCH($A6, '1_DCS_numerator_by_BEA'!$A$2:$A$74, 0)), 0) | E6: =C6*D6
A7: ='Crosswalk_BEA_to_ISIC'!A13 | B7: ='Crosswalk_BEA_to_ISIC'!C13 | C7: ='Crosswalk_BEA_to_ISIC'!E13 | D7: =IFERROR(INDEX('1_DCS_numerator_by_BEA'!$B$2:$B$74, MATCH($A7, '1_DCS_numerator_by_BEA'!$A$2:$A$74, 0)), 0) | E7: =C7*D7
A8: ='Crosswalk_BEA_to_ISIC'!A14 | B8: ='Crosswalk_BEA_to_ISIC'!C14 | C8: ='Crosswalk_BEA_to_ISIC'!E14 | D8: =IFERROR(INDEX('1_DCS_numerator_by_BEA'!$B$2:$B$74, MATCH($A8, '1_DCS_numerator_by_BEA'!$A$2:$A$74, 0)), 0) | E8: =C8*D8
A9: ='Crosswalk_BEA_to_ISIC'!A15 | B9: ='Crosswalk_BEA_to_ISIC'!C15 | C9: ='Crosswalk_BEA_to_ISIC'!E15 | D9: =IFERROR(INDEX('1_DCS_numerator_by_BEA'!$B$2:$B$74, MATCH($A9, '1_DCS_numerator_by_BEA'!$A$2:$A$74, 0)), 0) | E9: =C9*D9
A10: ='Crosswalk_BEA_to_ISIC'!A16 | B10: ='Crosswalk_BEA_to_ISIC'!C16 | C10: ='Crosswalk_BEA_to_ISIC'!E16 | D10: =IFERROR(INDEX('1_DCS_numerator_by_BEA'!$B$2:$B$74, MATCH($A10, '1_DCS_numerator_by_BEA'!$A$2:$A$74, 0)), 0) | E10: =C10*D10
A11: ='Crosswalk_BEA_to_ISIC'!A17 | B11: ='Crosswalk_BEA_to_ISIC'!C17 | C11: ='Crosswalk_BEA_to_ISIC'!E17 | D11: =IFERROR(INDEX('1_DCS_numerator_by_BEA'!$B$2:$B$74, MATCH($A11, '1_DCS_numerator_by_BEA'!$A$2:$A$74, 0)), 0) | E11: =C11*D11
A12: ='Crosswalk_BEA_to_ISIC'!A18 | B12: ='Crosswalk_BEA_to_ISIC'!C18 | C12: ='Crosswalk_BEA_to_ISIC'!E18 | D12: =IFERROR(INDEX('1_DCS_numerator_by_BEA'!$B$2:$B$74, MATCH($A12, '1_DCS_numerator_by_BEA'!$A$2:$A$74, 0)), 0) | E12: =C12*D12
A13: ='Crosswalk_BEA_to_ISIC'!A19 | B13: ='Crosswalk_BEA_to_ISIC'!C19 | C13: ='Crosswalk_BEA_to_ISIC'!E19 | D13: =IFERROR(INDEX('1_DCS_numerator_by_BEA'!$B$2:$B$74, MATCH($A13, '1_DCS_numerator_by_BEA'!$A$2:$A$74, 0)), 0) | E13: =C13*D13
A14: ='Crosswalk_BEA_to_ISIC'!A20 | B14: ='Crosswalk_BEA_to_ISIC'!C20 | C14: ='Crosswalk_BEA_to_ISIC'!E20 | D14: =IFERROR(INDEX('1_DCS_numerator_by_BEA'!$B$2:$B$74, MATCH($A14, '1_DCS_numerator_by_BEA'!$A$2:$A$74, 0)), 0) | E14: =C14*D14
... A81: ='Crosswalk_BEA_to_ISIC'!A87 | B81: ='Crosswalk_BEA_to_ISIC'!C87 | C81: ='Crosswalk_BEA_to_ISIC'!E87 | D81: =IFERROR(INDEX('1_DCS_numerator_by_BEA'!$B$2:$B$74, MATCH($A81, '1_DCS_numerator_by_BEA'!$A$2:$A$74, 0)), 0) | E81: =C81*D81
A83: STEP 2 - aggregate weighted values to 42 ISIC (no deflation; passthrough column C = B)
A84: ISIC_code | B84: aggregated_nominal | C84: value (no deflation)
A85: 01T03 | B85: =SUMIFS('6_Calc_DCS_num_ISIC'!$E$3:$E$81, '6_Calc_DCS_num_ISIC'!$B$3:$B$81, $A85) | C85: =B85
A86: 05 | B86: =SUMIFS('6_Calc_DCS_num_ISIC'!$E$3:$E$81, '6_Calc_DCS_num_ISIC'!$B$3:$B$81, $A86) | C86: =B86
A87: 06 | B87: =SUMIFS('6_Calc_DCS_num_ISIC'!$E$3:$E$81, '6_Calc_DCS_num_ISIC'!$B$3:$B$81, $A87) | C87: =B87
A88: 07T08 | B88: =SUMIFS('6_Calc_DCS_num_ISIC'!$E$3:$E$81, '6_Calc_DCS_num_ISIC'!$B$3:$B$81, $A88) | C88: =B88
A89: 09 | B89: =SUMIFS('6_Calc_DCS_num_ISIC'!$E$3:$E$81, '6_Calc_DCS_num_ISIC'!$B$3:$B$81, $A89) | C89: =B89
A90: 10T12 | B90: =SUMIFS('6_Calc_DCS_num_ISIC'!$E$3:$E$81, '6_Calc_DCS_num_ISIC'!$B$3:$B$81, $A90) | C90: =B90
A91: 13T15 | B91: =SUMIFS('6_Calc_DCS_num_ISIC'!$E$3:$E$81, '6_Calc_DCS_num_ISIC'!$B$3:$B$81, $A91) | C91: =B91
A92: 16 | B92: =SUMIFS('6_Calc_DCS_num_ISIC'!$E$3:$E$81, '6_Calc_DCS_num_ISIC'!$B$3:$B$81, $A92) | C92: =B92
A93: 17T18 | B93: =SUMIFS('6_Calc_DCS_num_ISIC'!$E$3:$E$81, '6_Calc_DCS_num_ISIC'!$B$3:$B$81, $A93) | C93: =B93
A94: 19 | B94: =SUMIFS('6_Calc_DCS_num_ISIC'!$E$3:$E$81, '6_Calc_DCS_num_ISIC'!$B$3:$B$81, $A94) | C94: =B94
A95: 20 | B95: =SUMIFS('6_Calc_DCS_num_ISIC'!$E$3:$E$81, '6_Calc_DCS_num_ISIC'!$B$3:$B$81, $A95) | C95: =B95
A96: 21 | B96: =SUMIFS('6_Calc_DCS_num_ISIC'!$E$3:$E$81, '6_Calc_DCS_num_ISIC'!$B$3:$B$81, $A96) | C96: =B96
... A126: 97T98 | B126: =SUMIFS('6_Calc_DCS_num_ISIC'!$E$3:$E$81, '6_Calc_DCS_num_ISIC'!$B$3:$B$81, $A126) | C126: =B126

Sheet 7_Calc_DCS_den_ISIC
A1: STEP 1 - read BEA code / ISIC code / weight live from the Crosswalk tab, pull each BEA value from the source tab, then weight it
A2: BEA_code | B2: ISIC_code | C2: allocation_weight | D2: BEA_value_nominal | E2: weighted_nominal
A3: ='Crosswalk_BEA_to_ISIC'!A9 | B3: ='Crosswalk_BEA_to_ISIC'!C9 | C3: ='Crosswalk_BEA_to_ISIC'!E9 | D3: =IFERROR(INDEX('2_DCS_denominator_by_BEA'!$B$2:$B$74, MATCH($A3, '2_DCS_denominator_by_BEA'!$A$2:$A$74, 0)), 0) | E3: =C3*D3
A4: ='Crosswalk_BEA_to_ISIC'!A10 | B4: ='Crosswalk_BEA_to_ISIC'!C10 | C4: ='Crosswalk_BEA_to_ISIC'!E10 | D4: =IFERROR(INDEX('2_DCS_denominator_by_BEA'!$B$2:$B$74, MATCH($A4, '2_DCS_denominator_by_BEA'!$A$2:$A$74, 0)), 0) | E4: =C4*D4
A5: ='Crosswalk_BEA_to_ISIC'!A11 | B5: ='Crosswalk_BEA_to_ISIC'!C11 | C5: ='Crosswalk_BEA_to_ISIC'!E11 | D5: =IFERROR(INDEX('2_DCS_denominator_by_BEA'!$B$2:$B$74, MATCH($A5, '2_DCS_denominator_by_BEA'!$A$2:$A$74, 0)), 0) | E5: =C5*D5
A6: ='Crosswalk_BEA_to_ISIC'!A12 | B6: ='Crosswalk_BEA_to_ISIC'!C12 | C6: ='Crosswalk_BEA_to_ISIC'!E12 | D6: =IFERROR(INDEX('2_DCS_denominator_by_BEA'!$B$2:$B$74, MATCH($A6, '2_DCS_denominator_by_BEA'!$A$2:$A$74, 0)), 0) | E6: =C6*D6
